Workbook

Sheet Cotacao
A1: Column1 | B1: 1 | C1: DATA inicial | D1: ABCB4 | E1: 06/27/2019 | F1: BBSE3 | G1: DATA final | H1: EGIE3 | I1: 06/27/2020 | J1: ENAT3 | K1: DATA | L1: ENBR3 | M1: DATA_1 | N1: ITSA4 | O1: DATA_2 | P1: ITUB3 | Q1: DATA_3 | R1: LEVE3 | S1: DATA_4 | T1: MRVE3 | U1: DATA_5 | V1: SAPR4 | W1: DATA_6 | X1: SDIL11 | Y1: DATA_7 | Z1: TAEE11 | AA1: DATA_8 | AB1: TRPL4 | AC1: DATA_9 | AD1: TUPY3 | AE1: DATA_10 | AF1: UNIP6 | AG1: DATA_11 | AH1: VALE3 | AI1: DATA_12 | AJ1: VIVT3 | AK1: DATA_13 | AL1: VULC3 | AM1: DATA_14 | AN1: BCFF11 | AO1: DATA_15 | AP1: HGCR11 | AQ1: DATA_16 | AR1: MXRF11 | AS1: DATA_17 | AT1: MBRF11 | AU1: DATA_18 | AV1: GGRC11 | AW1: DATA_19 | AX1: MFII11 | AY1: DATA_20 | AZ1: FLMA11 | BA1: DATA_21 | BB1: HGLG11 | BC1: DATA_22 | BD1: LCAM3 | BE1: DATA_23 | BF1: SQIA3 | BG1: DATA_24 | BH1: MDIA3 | BI1: DATA_25 | BJ1: KNRI11 | BK1: DATA_26 | BL1: WEGE3 | BM1: DATA_27 | BN1: B3SA3 | BO1: DATA_28 | BP1: PETR4 | BQ1: DATA_29 | BR1: PRIO3 | BS1: DATA_30 | BT1: TIET11 | BU1: DATA_31 | BV1: IBOV | BW1: DATA_32 | BX1: CESP6
B2: 2 | C2: Date | D2: Close | E2: Date | F2: Close | G2: Date | H2: Close | I2: Date | J2: Close | K2: Date | L2: Close | M2: Date | N2: Close | O2: Date | P2: Close | Q2: Date | R2: Close | S2: Date | T2: Close | U2: Date | V2: Close | W2: Date | X2: Close | Y2: Date | Z2: Close | AA2: Date | AB2: Close | AC2: Date | AD2: Close | AE2: Date | AF2: Close | AG2: Date | AH2: Close | AI2: Date | AJ2: Close | AK2: Date | AL2: Close | AM2: Date | AN2: Close | AO2: Date | AP2: Close | AQ2: Date | AR2: Close | AS2: Date | AT2: Close | AU2: Date | AV2: Close | AW2: Date | AX2: Close | AY2: Date | AZ2: Close | BA2: Date | BB2: Close | BC2: Date | BD2: Close | BE2: Date | BF2: Close | BG2: Date | BH2: Close | BI2: Date | BJ2: Close | BK2: Date | BL2: Close | BM2: Date | BN2: Close | BO2: Date | BP2: Close | BQ2: Date | BR2: Close | BS2: Date | BT2: Close | BU2: Date | BV2: Close | BW2: Date | BX2: Close
B3: 3 | C3: 6/27/2019 16:56:00 | D3: 19 | E3: 6/27/2019 16:56:00 | F3: 32.43 | G3: 6/27/2019 16:56:00 | H3: 42.69 | I3: 6/27/2019 16:56:00 | J3: 13.18 | K3: 6/27/2019 16:56:00 | L3: 19.06 | M3: 6/27/2019 16:56:00 | N3: 12.94 | O3: 6/27/2019 16:56:00 | P3: 31 | Q3: 6/27/2019 16:56:00 | R3: 24.25 | S3: 6/27/2019 16:56:00 | T3: 19.24 | U3: 6/27/2019 16:56:00 | V3: 4.79 | W3: 6/27/2019 16:56:00 | X3: 112.1 | Y3: 6/27/2019 16:56:00 | Z3: 27.1 | AA3: 6/27/2019 16:56:00 | AB3: 24.52 | AC3: 6/27/2019 16:56:00 | AD3: 20.33 | AE3: 6/27/2019 16:56:00 | AF3: 35.82 | AG3: 6/27/2019 16:56:00 | AH3: 51.7 | AI3: 6/27/2019 16:56:00 | AJ3: 42.99 | AK3: 6/27/2019 16:56:00 | AL3: 6.61 | AM3: 6/27/2019 16:56:00 | AN3: 88.58 | AO3: 6/27/2019 16:56:00 | AP3: 119.08 | AQ3: 6/27/2019 16:56:00 | AR3: 11.37 | AS3: 6/27/2019 16:56:00 | AT3: 1256.96 | AU3: 6/27/2019 16:56:00 | AV3: 140.4 | AW3: 6/27/2019 16:56:00 | AX3: 120.38 | AY3: 6/27/2019 16:56:00 | AZ3: 3.62 | BA3: 6/27/2019 16:56:00 | BB3: 148.16 | BC3: 6/27/2019 16:56:00 | BD3: 15.81 | BE3: 6/27/2019 16:56:00 | BF3: 9.55 | BG3: 6/27/2019 16:56:00 | BH3: 38.73 | BI3: 6/27/2019 16:56:00 | BJ3: 152.6 | BK3: 6/27/2019 16:56:00 | BL3: 21.36 | BM3: 6/27/2019 16:56:00 | BN3: 37.59 | BO3: 6/27/2019 16:56:00 | BP3: 27.23 | BQ3: 6/27/2019 16:56:00 | BR3: 15.45 | BS3: 6/27/2019 16:56:00 | BT3: 11.63 | BU3: 6/27/2019 16:56:00 | BV3: 100723,97 | BW3: 6/27/2019 16:56:00 | BX3: 26,41
B4: 4 | C4: 6/28/2019 16:56:00 | D4: 19.22 | E4: 6/28/2019 16:56:00 | F4: 32.38 | G4: 6/28/2019 16:56:00 | H4: 43.47 | I4: 6/28/2019 16:56:00 | J4: 12.78 | K4: 6/28/2019 16:56:00 | L4: 18.9 | M4: 6/28/2019 16:56:00 | N4: 12.89 | O4: 6/28/2019 16:56:00 | P4: 31.13 | Q4: 6/28/2019 16:56:00 | R4: 24.72 | S4: 6/28/2019 16:56:00 | T4: 19.57 | U4: 6/28/2019 16:56:00 | V4: 4.9 | W4: 6/28/2019 16:56:00 | X4: 114 | Y4: 6/28/2019 16:56:00 | Z4: 27.16 | AA4: 6/28/2019 16:56:00 | AB4: 24.74 | AC4: 6/28/2019 16:56:00 | AD4: 20.89 | AE4: 6/28/2019 16:56:00 | AF4: 35.65 | AG4: 6/28/2019 16:56:00 | AH4: 51.82 | AI4: 6/28/2019 16:56:00 | AJ4: 42.25 | AK4: 6/28/2019 16:56:00 | AL4: 6.69 | AM4: 6/28/2019 16:56:00 | AN4: 89.39 | AO4: 6/28/2019 16:56:00 | AP4: 119.75 | AQ4: 6/28/2019 16:56:00 | AR4: 11.41 | AS4: 6/28/2019 16:56:00 | AT4: 1268.98 | AU4: 6/28/2019 16:56:00 | AV4: 141.81 | AW4: 6/28/2019 16:56:00 | AX4: 121.1 | AY4: 6/28/2019 16:56:00 | AZ4: 3.64 | BA4: 6/28/2019 16:56:00 | BB4: 148.54 | BC4: 6/28/2019 16:56:00 | BD4: 16.29 | BE4: 6/28/2019 16:56:00 | BF4: 9.65 | BG4: 6/28/2019 16:56:00 | BH4: 38.96 | BI4: 6/28/2019 16:56:00 | BJ4: 154.23 | BK4: 6/28/2019 16:56:00 | BL4: 21.36 | BM4: 6/28/2019 16:56:00 | BN4: 37.46 | BO4: 6/28/2019 16:56:00 | BP4: 27.41 | BQ4: 6/28/2019 16:56:00 | BR4: 15.77 | BS4: 6/28/2019 16:56:00 | BT4: 11.77 | BU4: 6/28/2019 16:56:00 | BV4: 100967,2 | BW4: 6/28/2019 16:56:00 | BX4: 27,18
B5: 5 | C5: 7/1/2019 16:56:00 | D5: 19 | E5: 7/1/2019 16:56:00 | F5: 32.8 | G5: 7/1/2019 16:56:00 | H5: 43.5 | I5: 7/1/2019 16:56:00 | J5: 12.95 | K5: 7/1/2019 16:56:00 | L5: 18.66 | M5: 7/1/2019 16:56:00 | N5: 12.92 | O5: 7/1/2019 16:56:00 | P5: 31.11 | Q5: 7/1/2019 16:56:00 | R5: 24.98 | S5: 7/1/2019 16:56:00 | T5: 19.12 | U5: 7/1/2019 16:56:00 | V5: 4.8 | W5: 7/1/2019 16:56:00 | X5: 111.48 | Y5: 7/1/2019 16:56:00 | Z5: 27.4 | AA5: 7/1/2019 16:56:00 | AB5: 24.55 | AC5: 7/1/2019 16:56:00 | AD5: 21 | AE5: 7/1/2019 16:56:00 | AF5: 35.49 | AG5: 7/1/2019 16:56:00 | AH5: 53.65 | AI5: 7/1/2019 16:56:00 | AJ5: 41.6 | AK5: 7/1/2019 16:56:00 | AL5: 6.6 | AM5: 7/1/2019 16:56:00 | AN5: 89.6 | AO5: 7/1/2019 16:56:00 | AP5: 118.75 | AQ5: 7/1/2019 16:56:00 | AR5: 11.27 | AS5: 7/1/2019 16:56:00 | AT5: 1262.09 | AU5: 7/1/2019 16:56:00 | AV5: 142.96 | AW5: 7/1/2019 16:56:00 | AX5: 119.9 | AY5: 7/1/2019 16:56:00 | AZ5: 3.63 | BA5: 7/1/2019 16:56:00 | BB5: 151.64 | BC5: 7/1/2019 16:56:00 | BD5: 16.04 | BE5: 7/1/2019 16:56:00 | BF5: 9.74 | BG5: 7/1/2019 16:56:00 | BH5: 38.73 | BI5: 7/1/2019 16:56:00 | BJ5: 155.5 | BK5: 7/1/2019 16:56:00 | BL5: 21.58 | BM5: 7/1/2019 16:56:00 | BN5: 38.15 | BO5: 7/1/2019 16:56:00 | BP5: 27.26 | BQ5: 7/1/2019 16:56:00 | BR5: 15.91 | BS5: 7/1/2019 16:56:00 | BT5: 11.9 | BU5: 7/1/2019 16:56:00 | BV5: 101339,68 | BW5: 7/1/2019 16:56:00 | BX5: 27,48
B6: 6 | C6: 7/2/2019 16:56:00 | D6: 18.82 | E6: 7/2/2019 16:56:00 | F6: 32.6 | G6: 7/2/2019 16:56:00 | H6: 43.71 | I6: 7/2/2019 16:56:00 | J6: 12.87 | K6: 7/2/2019 16:56:00 | L6: 18.85 | M6: 7/2/2019 16:56:00 | N6: 12.78 | O6: 7/2/2019 16:56:00 | P6: 30.8 | Q6: 7/2/2019 16:56:00 | R6: 25.03 | S6: 7/2/2019 16:56:00 | T6: 19.4 | U6: 7/2/2019 16:56:00 | V6: 4.91 | W6: 7/2/2019 16:56:00 | X6: 111.25 | Y6: 7/2/2019 16:56:00 | Z6: 27.4 | AA6: 7/2/2019 16:56:00 | AB6: 24.41 | AC6: 7/2/2019 16:56:00 | AD6: 21 | AE6: 7/2/2019 16:56:00 | AF6: 35.1 | AG6: 7/2/2019 16:56:00 | AH6: 51.39 | AI6: 7/2/2019 16:56:00 | AJ6: 42.72 | AK6: 7/2/2019 16:56:00 | AL6: 6.48 | AM6: 7/2/2019 16:56:00 | AN6: 89.73 | AO6: 7/2/2019 16:56:00 | AP6: 118.05 | AQ6: 7/2/2019 16:56:00 | AR6: 11.31 | AS6: 7/2/2019 16:56:00 | AT6: 1266 | AU6: 7/2/2019 16:56:00 | AV6: 142.49 | AW6: 7/2/2019 16:56:00 | AX6: 120 | AY6: 7/2/2019 16:56:00 | AZ6: 3.63 | BA6: 7/2/2019 16:56:00 | BB6: 152.38 | BC6: 7/2/2019 16:56:00 | BD6: 15.8 | BE6: 7/2/2019 16:56:00 | BF6: 9.94 | BG6: 7/2/2019 16:56:00 | BH6: 39.5 | BI6: 7/2/2019 16:56:00 | BJ6: 155 | BK6: 7/2/2019 16:56:00 | BL6: 21.56 | BM6: 7/2/2019 16:56:00 | BN6: 37.55 | BO6: 7/2/2019 16:56:00 | BP6: 26.82 | BQ6: 7/2/2019 16:56:00 | BR6: 15.67 | BS6: 7/2/2019 16:56:00 | BT6: 11.53 | BU6: 7/2/2019 16:56:00 | BV6: 100605,17 | BW6: 7/2/2019 16:56:00 | BX6: 27,06
B7: 7 | C7: 7/3/2019 16:56:00 | D7: 18.78 | E7: 7/3/2019 16:56:00 | F7: 32.77 | G7: 7/3/2019 16:56:00 | H7: 44.06 | I7: 7/3/2019 16:56:00 | J7: 12.8 | K7: 7/3/2019 16:56:00 | L7: 19.3 | M7: 7/3/2019 16:56:00 | N7: 12.98 | O7: 7/3/2019 16:56:00 | P7: 31.22 | Q7: 7/3/2019 16:56:00 | R7: 24.86 | S7: 7/3/2019 16:56:00 | T7: 19.1 | U7: 7/3/2019 16:56:00 | V7: 4.95 | W7: 7/3/2019 16:56:00 | X7: 112 | Y7: 7/3/2019 16:56:00 | Z7: 27.67 | AA7: 7/3/2019 16:56:00 | AB7: 24.08 | AC7: 7/3/2019 16:56:00 | AD7: 20.82 | AE7: 7/3/2019 16:56:00 | AF7: 34.82 | AG7: 7/3/2019 16:56:00 | AH7: 51.29 | AI7: 7/3/2019 16:56:00 | AJ7: 43 | AK7: 7/3/2019 16:56:00 | AL7: 6.57 | AM7: 7/3/2019 16:56:00 | AN7: 90.87 | AO7: 7/3/2019 16:56:00 | AP7: 118.5 | AQ7: 7/3/2019 16:56:00 | AR7: 11.38 | AS7: 7/3/2019 16:56:00 | AT7: 1295 | AU7: 7/3/2019 16:56:00 | AV7: 146.6 | AW7: 7/3/2019 16:56:00 | AX7: 120.2 | AY7: 7/3/2019 16:56:00 | AZ7: 3.64 | BA7: 7/3/2019 16:56:00 | BB7: 153.5 | BC7: 7/3/2019 16:56:00 | BD7: 16 | BE7: 7/3/2019 16:56:00 | BF7: 10.08 | BG7: 7/3/2019 16:56:00 | BH7: 39.65 | BI7: 7/3/2019 16:56:00 | BJ7: 156 | BK7: 7/3/2019 16:56:00 | BL7: 21.7 | BM7: 7/3/2019 16:56:00 | BN7: 38.4 | BO7: 7/3/2019 16:56:00 | BP7: 27.13 | BQ7: 7/3/2019 16:56:00 | BR7: 16.09 | BS7: 7/3/2019 16:56:00 | BT7: 11.78 | BU7: 7/3/2019 16:56:00 | BV7: 102043,11 | BW7: 7/3/2019 16:56:00 | BX7: 27,51
B8: 8 | C8: 7/4/2019 16:56:00 | D8: 19.35 | E8: 7/4/2019 16:56:00 | F8: 33.09 | G8: 7/4/2019 16:56:00 | H8: 44.34 | I8: 7/4/2019 16:56:00 | J8: 12.97 | K8: 7/4/2019 16:56:00 | L8: 19.62 | M8: 7/4/2019 16:56:00 | N8: 13.15 | O8: 7/4/2019 16:56:00 | P8: 31.53 | Q8: 7/4/2019 16:56:00 | R8: 25.58 | S8: 7/4/2019 16:56:00 | T8: 19.17 | U8: 7/4/2019 16:56:00 | V8: 4.98 | W8: 7/4/2019 16:56:00 | X8: 110.97 | Y8: 7/4/2019 16:56:00 | Z8: 27.78 | AA8: 7/4/2019 16:56:00 | AB8: 24.07 | AC8: 7/4/2019 16:56:00 | AD8: 20.89 | AE8: 7/4/2019 16:56:00 | AF8: 35.11 | AG8: 7/4/2019 16:56:00 | AH8: 51.67 | AI8: 7/4/2019 16:56:00 | AJ8: 44.03 | AK8: 7/4/2019 16:56:00 | AL8: 6.75 | AM8: 7/4/2019 16:56:00 | AN8: 90.45 | AO8: 7/4/2019 16:56:00 | AP8: 118.28 | AQ8: 7/4/2019 16:56:00 | AR8: 11.47 | AS8: 7/4/2019 16:56:00 | AT8: 1289 | AU8: 7/4/2019 16:56:00 | AV8: 144.7 | AW8: 7/4/2019 16:56:00 | AX8: 120 | AY8: 7/4/2019 16:56:00 | AZ8: 3.62 | BA8: 7/4/2019 16:56:00 | BB8: 153.09 | BC8: 7/4/2019 16:56:00 | BD8: 16.07 | BE8: 7/4/2019 16:56:00 | BF8: 10.03 | BG8: 7/4/2019 16:56:00 | BH8: 39.81 | BI8: 7/4/2019 16:56:00 | BJ8: 153 | BK8: 7/4/2019 16:56:00 | BL8: 22.2 | BM8: 7/4/2019 16:56:00 | BN8: 39.74 | BO8: 7/4/2019 16:56:00 | BP8: 27.39 | BQ8: 7/4/2019 16:56:00 | BR8: 16.05 | BS8: 7/4/2019 16:56:00 | BT8: 11.97 | BU8: 7/4/2019 16:56:00 | BV8: 103636,17 | BW8: 7/4/2019 16:56:00 | BX8: 27,95
B9: 9 | C9: 7/5/2019 16:56:00 | D9: 18.85 | E9: 7/5/2019 16:56:00 | F9: 33.85 | G9: 7/5/2019 16:56:00 | H9: 44.55 | I9: 7/5/2019 16:56:00 | J9: 13.1 | K9: 7/5/2019 16:56:00 | L9: 19.48 | M9: 7/5/2019 16:56:00 | N9: 13.27 | O9: 7/5/2019 16:56:00 | P9: 31.8 | Q9: 7/5/2019 16:56:00 | R9: 25.59 | S9: 7/5/2019 16:56:00 | T9: 19.35 | U9: 7/5/2019 16:56:00 | V9: 4.89 | W9: 7/5/2019 16:56:00 | X9: 111 | Y9: 7/5/2019 16:56:00 | Z9: 28.03 | AA9: 7/5/2019 16:56:00 | AB9: 24.48 | AC9: 7/5/2019 16:56:00 | AD9: 20.88 | AE9: 7/5/2019 16:56:00 | AF9: 35.1 | AG9: 7/5/2019 16:56:00 | AH9: 50.36 | AI9: 7/5/2019 16:56:00 | AJ9: 43.65 | AK9: 7/5/2019 16:56:00 | AL9: 6.69 | AM9: 7/5/2019 16:56:00 | AN9: 90.51 | AO9: 7/5/2019 16:56:00 | AP9: 118.61 | AQ9: 7/5/2019 16:56:00 | AR9: 11.63 | AS9: 7/5/2019 16:56:00 | AT9: 1289.89 | AU9: 7/5/2019 16:56:00 | AV9: 144.6 | AW9: 7/5/2019 16:56:00 | AX9: 120.3 | AY9: 7/5/2019 16:56:00 | AZ9: 3.63 | BA9: 7/5/2019 16:56:00 | BB9: 153.09 | BC9: 7/5/2019 16:56:00 | BD9: 16.67 | BE9: 7/5/2019 16:56:00 | BF9: 10.24 | BG9: 7/5/2019 16:56:00 | BH9: 39.43 | BI9: 7/5/2019 16:56:00 | BJ9: 152.99 | BK9: 7/5/2019 16:56:00 | BL9: 22.4 | BM9: 7/5/2019 16:56:00 | BN9: 40.4 | BO9: 7/5/2019 16:56:00 | BP9: 27.4 | BQ9: 7/5/2019 16:56:00 | BR9: 16.4 | BS9: 7/5/2019 16:56:00 | BT9: 12.13 | BU9: 7/5/2019 16:56:00 | BV9: 104089,47 | BW9: 7/5/2019 16:56:00 | BX9: 28,47
B10: 10 | C10: 7/8/2019 16:56:00 | D10: 18.85 | E10: 7/8/2019 16:56:00 | F10: 33.51 | G10: 7/8/2019 16:56:00 | H10: 45.17 | I10: 7/8/2019 16:56:00 | J10: 14 | K10: 7/8/2019 16:56:00 | L10: 19.65 | M10: 7/8/2019 16:56:00 | N10: 13.28 | O10: 7/8/2019 16:56:00 | P10: 31.86 | Q10: 7/8/2019 16:56:00 | R10: 25.52 | S10: 7/8/2019 16:56:00 | T10: 19.63 | U10: 7/8/2019 16:56:00 | V10: 5.15 | W10: 7/8/2019 16:56:00 | X10: 111 | Y10: 7/8/2019 16:56:00 | Z10: 28.34 | AA10: 7/8/2019 16:56:00 | AB10: 25.12 | AC10: 7/8/2019 16:56:00 | AD10: 20.47 | AE10: 7/8/2019 16:56:00 | AF10: 36 | AG10: 7/8/2019 16:56:00 | AH10: 50.95 | AI10: 7/8/2019 16:56:00 | AJ10: 44.33 | AK10: 7/8/2019 16:56:00 | AL10: 7.36 | AM10: 7/8/2019 16:56:00 | AN10: 89.98 | AO10: 7/8/2019 16:56:00 | AP10: 118.9 | AQ10: 7/8/2019 16:56:00 | AR10: 11.61 | AS10: 7/8/2019 16:56:00 | AT10: 1293.29 | AU10: 7/8/2019 16:56:00 | AV10: 142.89 | AW10: 7/8/2019 16:56:00 | AX10: 120.3 | AY10: 7/8/2019 16:56:00 | AZ10: 3.64 | BA10: 7/8/2019 16:56:00 | BB10: 152.1 | BC10: 7/8/2019 16:56:00 | BD10: 17.27 | BE10: 7/8/2019 16:56:00 | BF10: 10.58 | BG10: 7/8/2019 16:56:00 | BH10: 38.71 | BI10: 7/8/2019 16:56:00 | BJ10: 152.7 | BK10: 7/8/2019 16:56:00 | BL10: 22.53 | BM10: 7/8/2019 16:56:00 | BN10: 40.3 | BO10: 7/8/2019 16:56:00 | BP10: 27.65 | BQ10: 7/8/2019 16:56:00 | BR10: 18 | BS10: 7/8/2019 16:56:00 | BT10: 12.5 | BU10: 7/8/2019 16:56:00 | BV10: 104530,22 | BW10: 7/8/2019 16:56:00 | BX10: 28,5
B11: 11 | C11: 7/10/2019 16:56:00 | D11: 19.2 | E11: 7/10/2019 16:56:00 | F11: 33.74 | G11: 7/10/2019 16:56:00 | H11: 46.16 | I11: 7/10/2019 16:56:00 | J11: 13.9 | K11: 7/10/2019 16:56:00 | L11: 19.96 | M11: 7/10/2019 16:56:00 | N11: 13.34 | O11: 7/10/2019 16:56:00 | P11: 31.57 | Q11: 7/10/2019 16:56:00 | R11: 25.34 | S11: 7/10/2019 16:56:00 | T11: 20.09 | U11: 7/10/2019 16:56:00 | V11: 5.17 | W11: 7/10/2019 16:56:00 | X11: 110.75 | Y11: 7/10/2019 16:56:00 | Z11: 28.69 | AA11: 7/10/2019 16:56:00 | AB11: 25.56 | AC11: 7/10/2019 16:56:00 | AD11: 20.56 | AE11: 7/10/2019 16:56:00 | AF11: 35.7 | AG11: 7/10/2019 16:56:00 | AH11: 52.13 | AI11: 7/10/2019 16:56:00 | AJ11: 45.9 | AK11: 7/10/2019 16:56:00 | AL11: 7.32 | AM11: 7/10/2019 16:56:00 | AN11: 89.95 | AO11: 7/10/2019 16:56:00 | AP11: 118.51 | AQ11: 7/10/2019 16:56:00 | AR11: 11.6 | AS11: 7/10/2019 16:56:00 | AT11: 1273 | AU11: 7/10/2019 16:56:00 | AV11: 142.53 | AW11: 7/10/2019 16:56:00 | AX11: 119.96 | AY11: 7/10/2019 16:56:00 | AZ11: 3.64 | BA11: 7/10/2019 16:56:00 | BB11: 151.22 | BC11: 7/10/2019 16:56:00 | BD11: 17.2 | BE11: 7/10/2019 16:56:00 | BF11: 11.24 | BG11: 7/10/2019 16:56:00 | BH11: 39.86 | BI11: 7/10/2019 16:56:00 | BJ11: 152.47 | BK11: 7/10/2019 16:56:00 | BL11: 23.69 | BM11: 7/10/2019 16:56:00 | BN11: 42.1 | BO11: 7/10/2019 16:56:00 | BP11: 28.07 | BQ11: 7/10/2019 16:56:00 | BR11: 18.17 | BS11: 7/10/2019 16:56:00 | BT11: 12.6 | BU11: 7/10/2019 16:56:00 | BV11: 105817,06 | BW11: 7/10/2019 16:56:00 | BX11: 28,51
B12: 12 | C12: 7/11/2019 16:56:00 | D12: 18.67 | E12: 7/11/2019 16:56:00 | F12: 33.17 | G12: 7/11/2019 16:56:00 | H12: 46.03 | I12: 7/11/2019 16:56:00 | J12: 13.75 | K12: 7/11/2019 16:56:00 | L12: 19.9 | M12: 7/11/2019 16:56:00 | N12: 13.2 | O12: 7/11/2019 16:56:00 | P12: 31.55 | Q12: 7/11/2019 16:56:00 | R12: 25.46 | S12: 7/11/2019 16:56:00 | T12: 19.98 | U12: 7/11/2019 16:56:00 | V12: 5.22 | W12: 7/11/2019 16:56:00 | X12: 109.77 | Y12: 7/11/2019 16:56:00 | Z12: 28.96 | AA12: 7/11/2019 16:56:00 | AB12: 25.63 | AC12: 7/11/2019 16:56:00 | AD12: 20.44 | AE12: 7/11/2019 16:56:00 | AF12: 35.64 | AG12: 7/11/2019 16:56:00 | AH12: 52.05 | AI12: 7/11/2019 16:56:00 | AJ12: 45.06 | AK12: 7/11/2019 16:56:00 | AL12: 7.3 | AM12: 7/11/2019 16:56:00 | AN12: 90.4 | AO12: 7/11/2019 16:56:00 | AP12: 119 | AQ12: 7/11/2019 16:56:00 | AR12: 11.51 | AS12: 7/11/2019 16:56:00 | AT12: 1275 | AU12: 7/11/2019 16:56:00 | AV12: 143.49 | AW12: 7/11/2019 16:56:00 | AX12: 118.71 | AY12: 7/11/2019 16:56:00 | AZ12: 3.65 | BA12: 7/11/2019 16:56:00 | BB12: 151.38 | BC12: 7/11/2019 16:56:00 | BD12: 17.28 | BE12: 7/11/2019 16:56:00 | BF12: 11.22 | BG12: 7/11/2019 16:56:00 | BH12: 41.19 | BI12: 7/11/2019 16:56:00 | BJ12: 151.4 | BK12: 7/11/2019 16:56:00 | BL12: 23.6 | BM12: 7/11/2019 16:56:00 | BN12: 41.16 | BO12: 7/11/2019 16:56:00 | BP12: 28.4 | BQ12: 7/11/2019 16:56:00 | BR12: 18.28 | BS12: 7/11/2019 16:56:00 | BT12: 12.53 | BU12: 7/11/2019 16:56:00 | BV12: 105146,44 | BW12: 7/11/2019 16:56:00 | BX12: 28,78
B13: 13 | C13: 7/12/2019 16:56:00 | D13: 18.61 | E13: 7/12/2019 16:56:00 | F13: 33.42 | G13: 7/12/2019 16:56:00 | H13: 46.5 | I13: 7/12/2019 16:56:00 | J13: 14.02 | K13: 7/12/2019 16:56:00 | L13: 19.64 | M13: 7/12/2019 16:56:00 | N13: 13 | O13: 7/12/2019 16:56:00 | P13: 31.38 | Q13: 7/12/2019 16:56:00 | R13: 25.22 | S13: 7/12/2019 16:56:00 | T13: 19.43 | U13: 7/12/2019 16:56:00 | V13: 5.11 | W13: 7/12/2019 16:56:00 | X13: 110.95 | Y13: 7/12/2019 16:56:00 | Z13: 28.48 | AA13: 7/12/2019 16:56:00 | AB13: 25.61 | AC13: 7/12/2019 16:56:00 | AD13: 20.41 | AE13: 7/12/2019 16:56:00 | AF13: 35.29 | AG13: 7/12/2019 16:56:00 | AH13: 51.81 | AI13: 7/12/2019 16:56:00 | AJ13: 44.83 | AK13: 7/12/2019 16:56:00 | AL13: 7.1 | AM13: 7/12/2019 16:56:00 | AN13: 90.69 | AO13: 7/12/2019 16:56:00 | AP13: 119 | AQ13: 7/12/2019 16:56:00 | AR13: 11.57 | AS13: 7/12/2019 16:56:00 | AT13: 1278.64 | AU13: 7/12/2019 16:56:00 | AV13: 141.9 | AW13: 7/12/2019 16:56:00 | AX13: 119.09 | AY13: 7/12/2019 16:56:00 | AZ13: 3.67 | BA13: 7/12/2019 16:56:00 | BB13: 152 | BC13: 7/12/2019 16:56:00 | BD13: 17.21 | BE13: 7/12/2019 16:56:00 | BF13: 11.24 | BG13: 7/12/2019 16:56:00 | BH13: 40 | BI13: 7/12/2019 16:56:00 | BJ13: 152.3 | BK13: 7/12/2019 16:56:00 | BL13: 23.09 | BM13: 7/12/2019 16:56:00 | BN13: 39.7 | BO13: 7/12/2019 16:56:00 | BP13: 28.53 | BQ13: 7/12/2019 16:56:00 | BR13: 18.77 | BS13: 7/12/2019 16:56:00 | BT13: 12.63 | BU13: 7/12/2019 16:56:00 | BV13: 103905,99 | BW13: 7/12/2019 16:56:00 | BX13: 29,15
B14: 14 | C14: 7/15/2019 16:56:00 | D14: 18.14 | E14: 7/15/2019 16:56:00 | F14: 33.37 | G14: 7/15/2019 16:56:00 | H14: 45.99 | I14: 7/15/2019 16:56:00 | J14: 13.85 | K14: 7/15/2019 16:56:00 | L14: 19.4 | M14: 7/15/2019 16:56:00 | N14: 12.95 | O14: 7/15/2019 16:56:00 | P14: 31.05 | Q14: 7/15/2019 16:56:00 | R14: 25 | S14: 7/15/2019 16:56:00 | T14: 19.27 | U14: 7/15/2019 16:56:00 | V14: 5.13 | W14: 7/15/2019 16:56:00 | X14: 110.29 | Y14: 7/15/2019 16:56:00 | Z14: 28.03 | AA14: 7/15/2019 16:56:00 | AB14: 25.2 | AC14: 7/15/2019 16:56:00 | AD14: 20.55 | AE14: 7/15/2019 16:56:00 | AF14: 35.1 | AG14: 7/15/2019 16:56:00 | AH14: 52.69 | AI14: 7/15/2019 16:56:00 | AJ14: 45.74 | AK14: 7/15/2019 16:56:00 | AL14: 6.96 | AM14: 7/15/2019 16:56:00 | AN14: 90.8 | AO14: 7/15/2019 16:56:00 | AP14: 118.73 | AQ14: 7/15/2019 16:56:00 | AR14: 11.63 | AS14: 7/15/2019 16:56:00 | AT14: 1255 | AU14: 7/15/2019 16:56:00 | AV14: 141.18 | AW14: 7/15/2019 16:56:00 | AX14: 119 | AY14: 7/15/2019 16:56:00 | AZ14: 3.7 | BA14: 7/15/2019 16:56:00 | BB14: 152.98 | BC14: 7/15/2019 16:56:00 | BD14: 16.92 | BE14: 7/15/2019 16:56:00 | BF14: 11.7 | BG14: 7/15/2019 16:56:00 | BH14: 38.8 | BI14: 7/15/2019 16:56:00 | BJ14: 152.5 | BK14: 7/15/2019 16:56:00 | BL14: 22.4 | BM14: 7/15/2019 16:56:00 | BN14: 39.74 | BO14: 7/15/2019 16:56:00 | BP14: 28.18 | BQ14: 7/15/2019 16:56:00 | BR14: 19.26 | BS14: 7/15/2019 16:56:00 | BT14: 12.69 | BU14: 7/15/2019 16:56:00 | BV14: 103802,69 | BW14: 7/15/2019 16:56:00 | BX14: 29,3
B15: 15 | C15: 7/16/2019 16:56:00 | D15: 18.18 | E15: 7/16/2019 16:56:00 | F15: 33.39 | G15: 7/16/2019 16:56:00 | H15: 46.4 | I15: 7/16/2019 16:56:00 | J15: 13.75 | K15: 7/16/2019 16:56:00 | L15: 19.15 | M15: 7/16/2019 16:56:00 | N15: 12.89 | O15: 7/16/2019 16:56:00 | P15: 31.16 | Q15: 7/16/2019 16:56:00 | R15: 24.95 | S15: 7/16/2019 16:56:00 | T15: 19.55 | U15: 7/16/2019 16:56:00 | V15: 5.13 | W15: 7/16/2019 16:56:00 | X15: 110.4 | Y15: 7/16/2019 16:56:00 | Z15: 27.82 | AA15: 7/16/2019 16:56:00 | AB15: 25.35 | AC15: 7/16/2019 16:56:00 | AD15: 20.05 | AE15: 7/16/2019 16:56:00 | AF15: 34.49 | AG15: 7/16/2019 16:56:00 | AH15: 53.05 | AI15: 7/16/2019 16:56:00 | AJ15: 46.17 | AK15: 7/16/2019 16:56:00 | AL15: 6.98 | AM15: 7/16/2019 16:56:00 | AN15: 91 | AO15: 7/16/2019 16:56:00 | AP15: 118.35 | AQ15: 7/16/2019 16:56:00 | AR15: 11.68 | AS15: 7/16/2019 16:56:00 | AT15: 1266.99 | AU15: 7/16/2019 16:56:00 | AV15: 141.82 | AW15: 7/16/2019 16:56:00 | AX15: 119.5 | AY15: 7/16/2019 16:56:00 | AZ15: 3.71 | BA15: 7/16/2019 16:56:00 | BB15: 156.38 | BC15: 7/16/2019 16:56:00 | BD15: 17.3 | BE15: 7/16/2019 16:56:00 | BF15: 11.93 | BG15: 7/16/2019 16:56:00 | BH15: 38.04 | BI15: 7/16/2019 16:56:00 | BJ15: 152.5 | BK15: 7/16/2019 16:56:00 | BL15: 22.51 | BM15: 7/16/2019 16:56:00 | BN15: 41 | BO15: 7/16/2019 16:56:00 | BP15: 27.83 | BQ15: 7/16/2019 16:56:00 | BR15: 18.3 | BS15: 7/16/2019 16:56:00 | BT15: 12.64 | BU15: 7/16/2019 16:56:00 | BV15: 103775,41 | BW15: 7/16/2019 16:56:00 | BX15: 29,24
B16: 16 | C16: 7/17/2019 16:56:00 | D16: 18.16 | E16: 7/17/2019 16:56:00 | F16: 33.81 | G16: 7/17/2019 16:56:00 | H16: 46.7 | I16: 7/17/2019 16:56:00 | J16: 13.5 | K16: 7/17/2019 16:56:00 | L16: 19.25 | M16: 7/17/2019 16:56:00 | N16: 12.93 | O16: 7/17/2019 16:56:00 | P16: 31 | Q16: 7/17/2019 16:56:00 | R16: 25.35 | S16: 7/17/2019 16:56:00 | T16: 19.32 | U16: 7/17/2019 16:56:00 | V16: 5.15 | W16: 7/17/2019 16:56:00 | X16: 111.39 | Y16: 7/17/2019 16:56:00 | Z16: 27.88 | AA16: 7/17/2019 16:56:00 | AB16: 25.4 | AC16: 7/17/2019 16:56:00 | AD16: 19.8 | AE16: 7/17/2019 16:56:00 | AF16: 34.45 | AG16: 7/17/2019 16:56:00 | AH16: 52.69 | AI16: 7/17/2019 16:56:00 | AJ16: 46.65 | AK16: 7/17/2019 16:56:00 | AL16: 7.16 | AM16: 7/17/2019 16:56:00 | AN16: 92 | AO16: 7/17/2019 16:56:00 | AP16: 118 | AQ16: 7/17/2019 16:56:00 | AR16: 11.74 | AS16: 7/17/2019 16:56:00 | AT16: 1250 | AU16: 7/17/2019 16:56:00 | AV16: 143 | AW16: 7/17/2019 16:56:00 | AX16: 119.18 | AY16: 7/17/2019 16:56:00 | AZ16: 3.9 | BA16: 7/17/2019 16:56:00 | BB16: 155.9 | BC16: 7/17/2019 16:56:00 | BD16: 17.27 | BE16: 7/17/2019 16:56:00 | BF16: 12.28 | BG16: 7/17/2019 16:56:00 | BH16: 37.85 | BI16: 7/17/2019 16:56:00 | BJ16: 152.45 | BK16: 7/17/2019 16:56:00 | BL16: 22.53 | BM16: 7/17/2019 16:56:00 | BN16: 41.29 | BO16: 7/17/2019 16:56:00 | BP16: 27.68 | BQ16: 7/17/2019 16:56:00 | BR16: 18.23 | BS16: 7/17/2019 16:56:00 | BT16: 12.69 | BU16: 7/17/2019 16:56:00 | BV16: 103855,53 | BW16: 7/17/2019 16:56:00 | BX16: 28,9
B17: 17 | C17: 7/18/2019 16:56:00 | D17: 18.4 | E17: 7/18/2019 16:56:00 | F17: 33.6 | G17: 7/18/2019 16:56:00 | H17: 46.74 | I17: 7/18/2019 16:56:00 | J17: 13.59 | K17: 7/18/2019 16:56:00 | L17: 19.24 | M17: 7/18/2019 16:56:00 | N17: 13.21 | O17: 7/18/2019 16:56:00 | P17: 31.73 | Q17: 7/18/2019 16:56:00 | R17: 25.18 | S17: 7/18/2019 16:56:00 | T17: 19.87 | U17: 7/18/2019 16:56:00 | V17: 5.23 | W17: 7/18/2019 16:56:00 | X17: 111.36 | Y17: 7/18/2019 16:56:00 | Z17: 28.15 | AA17: 7/18/2019 16:56:00 | AB17: 25.65 | AC17: 7/18/2019 16:56:00 | AD17: 19.79 | AE17: 7/18/2019 16:56:00 | AF17: 34.69 | AG17: 7/18/2019 16:56:00 | AH17: 52.59 | AI17: 7/18/2019 16:56:00 | AJ17: 45.74 | AK17: 7/18/2019 16:56:00 | AL17: 7.46 | AM17: 7/18/2019 16:56:00 | AN17: 91.8 | AO17: 7/18/2019 16:56:00 | AP17: 118.5 | AQ17: 7/18/2019 16:56:00 | AR17: 11.74 | AS17: 7/18/2019 16:56:00 | AT17: 1247 | AU17: 7/18/2019 16:56:00 | AV17: 142.5 | AW17: 7/18/2019 16:56:00 | AX17: 119.16 | AY17: 7/18/2019 16:56:00 | AZ17: 3.89 | BA17: 7/18/2019 16:56:00 | BB17: 155.81 | BC17: 7/18/2019 16:56:00 | BD17: 17.33 | BE17: 7/18/2019 16:56:00 | BF17: 13.23 | BG17: 7/18/2019 16:56:00 | BH17: 38.01 | BI17: 7/18/2019 16:56:00 | BJ17: 152.5 | BK17: 7/18/2019 16:56:00 | BL17: 22.75 | BM17: 7/18/2019 16:56:00 | BN17: 41.03 | BO17: 7/18/2019 16:56:00 | BP17: 27.51 | BQ17: 7/18/2019 16:56:00 | BR17: 18.17 | BS17: 7/18/2019 16:56:00 | BT17: 12.83 | BU17: 7/18/2019 16:56:00 | BV17: 104716,59 | BW17: 7/18/2019 16:56:00 | BX17: 29,2
B18: 18 | C18: 7/19/2019 16:56:00 | D18: 18.29 | E18: 7/19/2019 16:56:00 | F18: 32.7 | G18: 7/19/2019 16:56:00 | H18: 46.9 | I18: 7/19/2019 16:56:00 | J18: 13.38 | K18: 7/19/2019 16:56:00 | L18: 19.19 | M18: 7/19/2019 16:56:00 | N18: 13.05 | O18: 7/19/2019 16:56:00 | P18: 31.11 | Q18: 7/19/2019 16:56:00 | R18: 24.8 | S18: 7/19/2019 16:56:00 | T18: 19.02 | U18: 7/19/2019 16:56:00 | V18: 5.22 | W18: 7/19/2019 16:56:00 | X18: 109 | Y18: 7/19/2019 16:56:00 | Z18: 28.17 | AA18: 7/19/2019 16:56:00 | AB18: 25.6 | AC18: 7/19/2019 16:56:00 | AD18: 19.67 | AE18: 7/19/2019 16:56:00 | AF18: 34.64 | AG18: 7/19/2019 16:56:00 | AH18: 52.72 | AI18: 7/19/2019 16:56:00 | AJ18: 45.37 | AK18: 7/19/2019 16:56:00 | AL18: 7.35 | AM18: 7/19/2019 16:56:00 | AN18: 92.8 | AO18: 7/19/2019 16:56:00 | AP18: 118 | AQ18: 7/19/2019 16:56:00 | AR18: 11.75 | AS18: 7/19/2019 16:56:00 | AT18: 1250.1 | AU18: 7/19/2019 16:56:00 | AV18: 144 | AW18: 7/19/2019 16:56:00 | AX18: 119 | AY18: 7/19/2019 16:56:00 | AZ18: 3.9 | BA18: 7/19/2019 16:56:00 | BB18: 154.51 | BC18: 7/19/2019 16:56:00 | BD18: 16.97 | BE18: 7/19/2019 16:56:00 | BF18: 14.1 | BG18: 7/19/2019 16:56:00 | BH18: 38.65 | BI18: 7/19/2019 16:56:00 | BJ18: 152.4 | BK18: 7/19/2019 16:56:00 | BL18: 22.79 | BM18: 7/19/2019 16:56:00 | BN18: 40.38 | BO18: 7/19/2019 16:56:00 | BP18: 27.44 | BQ18: 7/19/2019 16:56:00 | BR18: 17.9 | BS18: 7/19/2019 16:56:00 | BT18: 12.59 | BU18: 7/19/2019 16:56:00 | BV18: 103451,93 | BW18: 7/19/2019 16:56:00 | BX18: 28,57
B19: 19 | C19: 7/22/2019 16:56:00 | D19: 18.44 | E19: 7/22/2019 16:56:00 | F19: 33.12 | G19: 7/22/2019 16:56:00 | H19: 47.05 | I19: 7/22/2019 16:56:00 | J19: 13.46 | K19: 7/22/2019 16:56:00 | L19: 19.62 | M19: 7/22/2019 16:56:00 | N19: 13.25 | O19: 7/22/2019 16:56:00 | P19: 31.55 | Q19: 7/22/2019 16:56:00 | R19: 24.84 | S19: 7/22/2019 16:56:00 | T19: 18.47 | U19: 7/22/2019 16:56:00 | V19: 5.22 | W19: 7/22/2019 16:56:00 | X19: 109.2 | Y19: 7/22/2019 16:56:00 | Z19: 28.42 | AA19: 7/22/2019 16:56:00 | AB19: 26.11 | AC19: 7/22/2019 16:56:00 | AD19: 19.74 | AE19: 7/22/2019 16:56:00 | AF19: 34.69 | AG19: 7/22/2019 16:56:00 | AH19: 52.45 | AI19: 7/22/2019 16:56:00 | AJ19: 45.28 | AK19: 7/22/2019 16:56:00 | AL19: 7.28 | AM19: 7/22/2019 16:56:00 | AN19: 92.3 | AO19: 7/22/2019 16:56:00 | AP19: 118.53 | AQ19: 7/22/2019 16:56:00 | AR19: 11.82 | AS19: 7/22/2019 16:56:00 | AT19: 1230 | AU19: 7/22/2019 16:56:00 | AV19: 144.1 | AW19: 7/22/2019 16:56:00 | AX19: 119.03 | AY19: 7/22/2019 16:56:00 | AZ19: 3.95 | BA19: 7/22/2019 16:56:00 | BB19: 157.1 | BC19: 7/22/2019 16:56:00 | BD19: 16.96 | BE19: 7/22/2019 16:56:00 | BF19: 13.27 | BG19: 7/22/2019 16:56:00 | BH19: 39 | BI19: 7/22/2019 16:56:00 | BJ19: 152.4 | BK19: 7/22/2019 16:56:00 | BL19: 22.6 | BM19: 7/22/2019 16:56:00 | BN19: 41.35 | BO19: 7/22/2019 16:56:00 | BP19: 27.49 | BQ19: 7/22/2019 16:56:00 | BR19: 17.92 | BS19: 7/22/2019 16:56:00 | BT19: 12.65 | BU19: 7/22/2019 16:56:00 | BV19: 103949,46 | BW19: 7/22/2019 16:56:00 | BX19: 28,7
B20: 20 | C20: 7/23/2019 16:56:00 | D20: 18.51 | E20: 7/23/2019 16:56:00 | F20: 32.87 | G20: 7/23/2019 16:56:00 | H20: 46.6 | I20: 7/23/2019 16:56:00 | J20: 13.5 | K20: 7/23/2019 16:56:00 | L20: 19.67 | M20: 7/23/2019 16:56:00 | N20: 13.32 | O20: 7/23/2019 16:56:00 | P20: 31.57 | Q20: 7/23/2019 16:56:00 | R20: 24.9 | S20: 7/23/2019 16:56:00 | T20: 18.73 | U20: 7/23/2019 16:56:00 | V20: 5.27 | W20: 7/23/2019 16:56:00 | X20: 109 | Y20: 7/23/2019 16:56:00 | Z20: 28.43 | AA20: 7/23/2019 16:56:00 | AB20: 26.07 | AC20: 7/23/2019 16:56:00 | AD20: 19.82 | AE20: 7/23/2019 16:56:00 | AF20: 34.3 | AG20: 7/23/2019 16:56:00 | AH20: 51.76 | AI20: 7/23/2019 16:56:00 | AJ20: 46.39 | AK20: 7/23/2019 16:56:00 | AL20: 7.2 | AM20: 7/23/2019 16:56:00 | AN20: 93.3 | AO20: 7/23/2019 16:56:00 | AP20: 119.71 | AQ20: 7/23/2019 16:56:00 | AR20: 11.79 | AS20: 7/23/2019 16:56:00 | AT20: 1231 | AU20: 7/23/2019 16:56:00 | AV20: 143.88 | AW20: 7/23/2019 16:56:00 | AX20: 119.35 | AY20: 7/23/2019 16:56:00 | AZ20: 3.99 | BA20: 7/23/2019 16:56:00 | BB20: 158.19 | BC20: 7/23/2019 16:56:00 | BD20: 16.92 | BE20: 7/23/2019 16:56:00 | BF20: 13.08 | BG20: 7/23/2019 16:56:00 | BH20: 38.31 | BI20: 7/23/2019 16:56:00 | BJ20: 152.2 | BK20: 7/23/2019 16:56:00 | BL20: 22.58 | BM20: 7/23/2019 16:56:00 | BN20: 40.75 | BO20: 7/23/2019 16:56:00 | BP20: 27.52 | BQ20: 7/23/2019 16:56:00 | BR20: 17.9 | BS20: 7/23/2019 16:56:00 | BT20: 12.73 | BU20: 7/23/2019 16:56:00 | BV20: 103704,28 | BW20: 7/23/2019 16:56:00 | BX20: 28,3
B21: 21 | C21: 7/24/2019 16:56:00 | D21: 18.67 | E21: 7/24/2019 16:56:00 | F21: 32.53 | G21: 7/24/2019 16:56:00 | H21: 46.95 | I21: 7/24/2019 16:56:00 | J21: 13.16 | K21: 7/24/2019 16:56:00 | L21: 19.55 | M21: 7/24/2019 16:56:00 | N21: 13.3 | O21: 7/24/2019 16:56:00 | P21: 31.68 | Q21: 7/24/2019 16:56:00 | R21: 24.76 | S21: 7/24/2019 16:56:00 | T21: 18.8 | U21: 7/24/2019 16:56:00 | V21: 5.17 | W21: 7/24/2019 16:56:00 | X21: 105.01 | Y21: 7/24/2019 16:56:00 | Z21: 28.38 | AA21: 7/24/2019 16:56:00 | AB21: 25.95 | AC21: 7/24/2019 16:56:00 | AD21: 20.05 | AE21: 7/24/2019 16:56:00 | AF21: 34.7 | AG21: 7/24/2019 16:56:00 | AH21: 50.65 | AI21: 7/24/2019 16:56:00 | AJ21: 45.4 | AK21: 7/24/2019 16:56:00 | AL21: 7.08 | AM21: 7/24/2019 16:56:00 | AN21: 92.78 | AO21: 7/24/2019 16:56:00 | AP21: 119.29 | AQ21: 7/24/2019 16:56:00 | AR21: 11.78 | AS21: 7/24/2019 16:56:00 | AT21: 1235 | AU21: 7/24/2019 16:56:00 | AV21: 143.28 | AW21: 7/24/2019 16:56:00 | AX21: 119.68 | AY21: 7/24/2019 16:56:00 | AZ21: 4.25 | BA21: 7/24/2019 16:56:00 | BB21: 158.59 | BC21: 7/24/2019 16:56:00 | BD21: 16.67 | BE21: 7/24/2019 16:56:00 | BF21: 12.73 | BG21: 7/24/2019 16:56:00 | BH21: 38.68 | BI21: 7/24/2019 16:56:00 | BJ21: 152.46 | BK21: 7/24/2019 16:56:00 | BL21: 23 | BM21: 7/24/2019 16:56:00 | BN21: 42.53 | BO21: 7/24/2019 16:56:00 | BP21: 27.35 | BQ21: 7/24/2019 16:56:00 | BR21: 18.27 | BS21: 7/24/2019 16:56:00 | BT21: 12.65 | BU21: 7/24/2019 16:56:00 | BV21: 104119,54 | BW21: 7/24/2019 16:56:00 | BX21: 27,5
B22: 22 | C22: 7/25/2019 16:56:00 | D22: 18.16 | E22: 7/25/2019 16:56:00 | F22: 32.49 | G22: 7/25/2019 16:56:00 | H22: 46.73 | I22: 7/25/2019 16:56:00 | J22: 13.12 | K22: 7/25/2019 16:56:00 | L22: 19.07 | M22: 7/25/2019 16:56:00 | N22: 12.9 | O22: 7/25/2019 16:56:00 | P22: 30.74 | Q22: 7/25/2019 16:56:00 | R22: 24.9 | S22: 7/25/2019 16:56:00 | T22: 18.6 | U22: 7/25/2019 16:56:00 | V22: 5.18 | W22: 7/25/2019 16:56:00 | X22: 108.19 | Y22: 7/25/2019 16:56:00 | Z22: 28.1 | AA22: 7/25/2019 16:56:00 | AB22: 25.7 | AC22: 7/25/2019 16:56:00 | AD22: 20.04 | AE22: 7/25/2019 16:56:00 | AF22: 34.1 | AG22: 7/25/2019 16:56:00 | AH22: 50.49 | AI22: 7/25/2019 16:56:00 | AJ22: 44.96 | AK22: 7/25/2019 16:56:00 | AL22: 7 | AM22: 7/25/2019 16:56:00 | AN22: 93.5 | AO22: 7/25/2019 16:56:00 | AP22: 117.42 | AQ22: 7/25/2019 16:56:00 | AR22: 11.77 | AS22: 7/25/2019 16:56:00 | AT22: 1230 | AU22: 7/25/2019 16:56:00 | AV22: 141.98 | AW22: 7/25/2019 16:56:00 | AX22: 119.89 | AY22: 7/25/2019 16:56:00 | AZ22: 4.2 | BA22: 7/25/2019 16:56:00 | BB22: 158.7 | BC22: 7/25/2019 16:56:00 | BD22: 16.49 | BE22: 7/25/2019 16:56:00 | BF22: 13 | BG22: 7/25/2019 16:56:00 | BH22: 38.4 | BI22: 7/25/2019 16:56:00 | BJ22: 150.01 | BK22: 7/25/2019 16:56:00 | BL22: 22.79 | BM22: 7/25/2019 16:56:00 | BN22: 41.9 | BO22: 7/25/2019 16:56:00 | BP22: 26.89 | BQ22: 7/25/2019 16:56:00 | BR22: 17.8 | BS22: 7/25/2019 16:56:00 | BT22: 12.64 | BU22: 7/25/2019 16:56:00 | BV22: 102654,58 | BW22: 7/25/2019 16:56:00 | BX22: 27,37
B23: 23 | C23: 7/26/2019 16:56:00 | D23: 18.3 | E23: 7/26/2019 16:56:00 | F23: 32.6 | G23: 7/26/2019 16:56:00 | H23: 47.81 | I23: 7/26/2019 16:56:00 | J23: 12.99 | K23: 7/26/2019 16:56:00 | L23: 19.26 | M23: 7/26/2019 16:56:00 | N23: 13.01 | O23: 7/26/2019 16:56:00 | P23: 31.1 | Q23: 7/26/2019 16:56:00 | R23: 24.8 | S23: 7/26/2019 16:56:00 | T23: 19.33 | U23: 7/26/2019 16:56:00 | V23: 5.2 | W23: 7/26/2019 16:56:00 | X23: 110 | Y23: 7/26/2019 16:56:00 | Z23: 27.88 | AA23: 7/26/2019 16:56:00 | AB23: 24.75 | AC23: 7/26/2019 16:56:00 | AD23: 19.9 | AE23: 7/26/2019 16:56:00 | AF23: 33.86 | AG23: 7/26/2019 16:56:00 | AH23: 50.23 | AI23: 7/26/2019 16:56:00 | AJ23: 44.7 | AK23: 7/26/2019 16:56:00 | AL23: 6.95 | AM23: 7/26/2019 16:56:00 | AN23: 93.9 | AO23: 7/26/2019 16:56:00 | AP23: 118.23 | AQ23: 7/26/2019 16:56:00 | AR23: 11.81 | AS23: 7/26/2019 16:56:00 | AT23: 1230.5 | AU23: 7/26/2019 16:56:00 | AV23: 143.12 | AW23: 7/26/2019 16:56:00 | AX23: 120 | AY23: 7/26/2019 16:56:00 | AZ23: 4.03 | BA23: 7/26/2019 16:56:00 | BB23: 158.9 | BC23: 7/26/2019 16:56:00 | BD23: 16.39 | BE23: 7/26/2019 16:56:00 | BF23: 13.08 | BG23: 7/26/2019 16:56:00 | BH23: 38.05 | BI23: 7/26/2019 16:56:00 | BJ23: 152 | BK23: 7/26/2019 16:56:00 | BL23: 23.36 | BM23: 7/26/2019 16:56:00 | BN23: 42.14 | BO23: 7/26/2019 16:56:00 | BP23: 26.14 | BQ23: 7/26/2019 16:56:00 | BR23: 17.76 | BS23: 7/26/2019 16:56:00 | BT23: 12.6 | BU23: 7/26/2019 16:56:00 | BV23: 102818,93 | BW23: 7/26/2019 16:56:00 | BX23: 28
B24: 24 | C24: 7/29/2019 16:56:00 | D24: 18.3 | E24: 7/29/2019 16:56:00 | F24: 32.61 | G24: 7/29/2019 16:56:00 | H24: 48.53 | I24: 7/29/2019 16:56:00 | J24: 12.79 | K24: 7/29/2019 16:56:00 | L24: 19.3 | M24: 7/29/2019 16:56:00 | N24: 12.99 | O24: 7/29/2019 16:56:00 | P24: 31.12 | Q24: 7/29/2019 16:56:00 | R24: 24.81 | S24: 7/29/2019 16:56:00 | T24: 19.59 | U24: 7/29/2019 16:56:00 | V24: 5.18 | W24: 7/29/2019 16:56:00 | X24: 110.4 | Y24: 7/29/2019 16:56:00 | Z24: 27.68 | AA24: 7/29/2019 16:56:00 | AB24: 24.46 | AC24: 7/29/2019 16:56:00 | AD24: 19.99 | AE24: 7/29/2019 16:56:00 | AF24: 33.36 | AG24: 7/29/2019 16:56:00 | AH24: 50.26 | AI24: 7/29/2019 16:56:00 | AJ24: 44.27 | AK24: 7/29/2019 16:56:00 | AL24: 6.82 | AM24: 7/29/2019 16:56:00 | AN24: 94 | AO24: 7/29/2019 16:56:00 | AP24: 116.9 | AQ24: 7/29/2019 16:56:00 | AR24: 11.84 | AS24: 7/29/2019 16:56:00 | AT24: 1225.01 | AU24: 7/29/2019 16:56:00 | AV24: 144 | AW24: 7/29/2019 16:56:00 | AX24: 120.37 | AY24: 7/29/2019 16:56:00 | AZ24: 4.15 | BA24: 7/29/2019 16:56:00 | BB24: 159.75 | BC24: 7/29/2019 16:56:00 | BD24: 16.62 | BE24: 7/29/2019 16:56:00 | BF24: 12.92 | BG24: 7/29/2019 16:56:00 | BH24: 39.08 | BI24: 7/29/2019 16:56:00 | BJ24: 152.65 | BK24: 7/29/2019 16:56:00 | BL24: 23.58 | BM24: 7/29/2019 16:56:00 | BN24: 42.62 | BO24: 7/29/2019 16:56:00 | BP24: 26.38 | BQ24: 7/29/2019 16:56:00 | BR24: 17.66 | BS24: 7/29/2019 16:56:00 | BT24: 12.55 | BU24: 7/29/2019 16:56:00 | BV24: 103482,63 | BW24: 7/29/2019 16:56:00 | BX24: 28,72
B25: 25 | C25: 7/30/2019 16:56:00 | D25: 18.26 | E25: 7/30/2019 16:56:00 | F25: 32.52 | G25: 7/30/2019 16:56:00 | H25: 48.85 | I25: 7/30/2019 16:56:00 | J25: 13.22 | K25: 7/30/2019 16:56:00 | L25: 19.28 | M25: 7/30/2019 16:56:00 | N25: 12.78 | O25: 7/30/2019 16:56:00 | P25: 30.37 | Q25: 7/30/2019 16:56:00 | R25: 24.8 | S25: 7/30/2019 16:56:00 | T25: 20.06 | U25: 7/30/2019 16:56:00 | V25: 5.3 | W25: 7/30/2019 16:56:00 | X25: 112.1 | Y25: 7/30/2019 16:56:00 | Z25: 27.97 | AA25: 7/30/2019 16:56:00 | AB25: 24.5 | AC25: 7/30/2019 16:56:00 | AD25: 20.11 | AE25: 7/30/2019 16:56:00 | AF25: 33.75 | AG25: 7/30/2019 16:56:00 | AH25: 50.01 | AI25: 7/30/2019 16:56:00 | AJ25: 44.2 | AK25: 7/30/2019 16:56:00 | AL25: 6.99 | AM25: 7/30/2019 16:56:00 | AN25: 94.5 | AO25: 7/30/2019 16:56:00 | AP25: 115.95 | AQ25: 7/30/2019 16:56:00 | AR25: 11.93 | AS25: 7/30/2019 16:56:00 | AT25: 1224.5 | AU25: 7/30/2019 16:56:00 | AV25: 144.32 | AW25: 7/30/2019 16:56:00 | AX25: 120.45 | AY25: 7/30/2019 16:56:00 | AZ25: 4.14 | BA25: 7/30/2019 16:56:00 | BB25: 159.8 | BC25: 7/30/2019 16:56:00 | BD25: 16.66 | BE25: 7/30/2019 16:56:00 | BF25: 12.65 | BG25: 7/30/2019 16:56:00 | BH25: 39.48 | BI25: 7/30/2019 16:56:00 | BJ25: 152.85 | BK25: 7/30/2019 16:56:00 | BL25: 24 | BM25: 7/30/2019 16:56:00 | BN25: 43.13 | BO25: 7/30/2019 16:56:00 | BP25: 26.24 | BQ25: 7/30/2019 16:56:00 | BR25: 17.84 | BS25: 7/30/2019 16:56:00 | BT25: 12.79 | BU25: 7/30/2019 16:56:00 | BV25: 102932,76 | BW25: 7/30/2019 16:56:00 | BX25: 28,67
B26: 26 | C26: 7/31/2019 16:56:00 | D26: 17.93 | E26: 7/31/2019 16:56:00 | F26: 32.45 | G26: 7/31/2019 16:56:00 | H26: 48.27 | I26: 7/31/2019 16:56:00 | J26: 13.25 | K26: 7/31/2019 16:56:00 | L26: 19.29 | M26: 7/31/2019 16:56:00 | N26: 12.47 | O26: 7/31/2019 16:56:00 | P26: 29.9 | Q26: 7/31/2019 16:56:00 | R26: 24.63 | S26: 7/31/2019 16:56:00 | T26: 20.28 | U26: 7/31/2019 16:56:00 | V26: 5.31 | W26: 7/31/2019 16:56:00 | X26: 114 | Y26: 7/31/2019 16:56:00 | Z26: 27.82 | AA26: 7/31/2019 16:56:00 | AB26: 24.2 | AC26: 7/31/2019 16:56:00 | AD26: 19.21 | AE26: 7/31/2019 16:56:00 | AF26: 33.71 | AG26: 7/31/2019 16:56:00 | AH26: 49.81 | AI26: 7/31/2019 16:56:00 | AJ26: 45 | AK26: 7/31/2019 16:56:00 | AL26: 7.1 | AM26: 7/31/2019 16:56:00 | AN26: 96.99 | AO26: 7/31/2019 16:56:00 | AP26: 116.05 | AQ26: 7/31/2019 16:56:00 | AR26: 11.96 | AS26: 7/31/2019 16:56:00 | AT26: 1235 | AU26: 7/31/2019 16:56:00 | AV26: 144.9 | AW26: 7/31/2019 16:56:00 | AX26: 121.87 | AY26: 7/31/2019 16:56:00 | AZ26: 4.25 | BA26: 7/31/2019 16:56:00 | BB26: 159.85 | BC26: 7/31/2019 16:56:00 | BD26: 16.67 | BE26: 7/31/2019 16:56:00 | BF26: 12.58 | BG26: 7/31/2019 16:56:00 | BH26: 39.13 | BI26: 7/31/2019 16:56:00 | BJ26: 153.49 | BK26: 7/31/2019 16:56:00 | BL26: 23.82 | BM26: 7/31/2019 16:56:00 | BN26: 42.19 | BO26: 7/31/2019 16:56:00 | BP26: 26.08 | BQ26: 7/31/2019 16:56:00 | BR26: 17.6 | BS26: 7/31/2019 16:56:00 | BT26: 12.79 | BU26: 7/31/2019 16:56:00 | BV26: 101812,13 | BW26: 7/31/2019 16:56:00 | BX26: 28,99
B27: 27 | C27: 8/1/2019 16:56:00 | D27: 17.7 | E27: 8/1/2019 16:56:00 | F27: 32.18 | G27: 8/1/2019 16:56:00 | H27: 48.1 | I27: 8/1/2019 16:56:00 | J27: 12.7 | K27: 8/1/2019 16:56:00 | L27: 19.6 | M27: 8/1/2019 16:56:00 | N27: 12.55 | O27: 8/1/2019 16:56:00 | P27: 29.99 | Q27: 8/1/2019 16:56:00 | R27: 24.64 | S27: 8/1/2019 16:56:00 | T27: 20.95 | U27: 8/1/2019 16:56:00 | V27: 5.36 | W27: 8/1/2019 16:56:00 | X27: 114 | Y27: 8/1/2019 16:56:00 | Z27: 28.31 | AA27: 8/1/2019 16:56:00 | AB27: 24.55 | AC27: 8/1/2019 16:56:00 | AD27: 18.56 | AE27: 8/1/2019 16:56:00 | AF27: 33 | AG27: 8/1/2019 16:56:00 | AH27: 48.4 | AI27: 8/1/2019 16:56:00 | AJ27: 45.01 | AK27: 8/1/2019 16:56:00 | AL27: 7.06 | AM27: 8/1/2019 16:56:00 | AN27: 97.11 | AO27: 8/1/2019 16:56:00 | AP27: 116 | AQ27: 8/1/2019 16:56:00 | AR27: 11.79 | AS27: 8/1/2019 16:56:00 | AT27: 1234 | AU27: 8/1/2019 16:56:00 | AV27: 144 | AW27: 8/1/2019 16:56:00 | AX27: 120.1 | AY27: 8/1/2019 16:56:00 | AZ27: 4.28 | BA27: 8/1/2019 16:56:00 | BB27: 154.98 | BC27: 8/1/2019 16:56:00 | BD27: 17.33 | BE27: 8/1/2019 16:56:00 | BF27: 12.88 | BG27: 8/1/2019 16:56:00 | BH27: 39.52 | BI27: 8/1/2019 16:56:00 | BJ27: 152.78 | BK27: 8/1/2019 16:56:00 | BL27: 23.43 | BM27: 8/1/2019 16:56:00 | BN27: 42.85 | BO27: 8/1/2019 16:56:00 | BP27: 26.25 | BQ27: 8/1/2019 16:56:00 | BR27: 17.15 | BS27: 8/1/2019 16:56:00 | BT27: 12.74 | BU27: 8/1/2019 16:56:00 | BV27: 102125,94 | BW27: 8/1/2019 16:56:00 | BX27: 29,03
B28: 28 | C28: 8/2/2019 16:56:00 | D28: 17.86 | E28: 8/2/2019 16:56:00 | F28: 32.4 | G28: 8/2/2019 16:56:00 | H28: 48.33 | I28: 8/2/2019 16:56:00 | J28: 12.62 | K28: 8/2/2019 16:56:00 | L28: 19.85 | M28: 8/2/2019 16:56:00 | N28: 12.46 | O28: 8/2/2019 16:56:00 | P28: 29.96 | Q28: 8/2/2019 16:56:00 | R28: 24.6 | S28: 8/2/2019 16:56:00 | T28: 20.9 | U28: 8/2/2019 16:56:00 | V28: 5.24 | W28: 8/2/2019 16:56:00 | X28: 116 | Y28: 8/2/2019 16:56:00 | Z28: 28.3 | AA28: 8/2/2019 16:56:00 | AB28: 24.74 | AC28: 8/2/2019 16:56:00 | AD28: 18.46 | AE28: 8/2/2019 16:56:00 | AF28: 32.6 | AG28: 8/2/2019 16:56:00 | AH28: 47.84 | AI28: 8/2/2019 16:56:00 | AJ28: 45.59 | AK28: 8/2/2019 16:56:00 | AL28: 6.97 | AM28: 8/2/2019 16:56:00 | AN28: 98.6 | AO28: 8/2/2019 16:56:00 | AP28: 115.78 | AQ28: 8/2/2019 16:56:00 | AR28: 11.77 | AS28: 8/2/2019 16:56:00 | AT28: 1237 | AU28: 8/2/2019 16:56:00 | AV28: 142 | AW28: 8/2/2019 16:56:00 | AX28: 120.01 | AY28: 8/2/2019 16:56:00 | AZ28: 4.28 | BA28: 8/2/2019 16:56:00 | BB28: 154.02 | BC28: 8/2/2019 16:56:00 | BD28: 17.13 | BE28: 8/2/2019 16:56:00 | BF28: 12.94 | BG28: 8/2/2019 16:56:00 | BH28: 39.6 | BI28: 8/2/2019 16:56:00 | BJ28: 154.1 | BK28: 8/2/2019 16:56:00 | BL28: 23.74 | BM28: 8/2/2019 16:56:00 | BN28: 43.12 | BO28: 8/2/2019 16:56:00 | BP28: 26.52 | BQ28: 8/2/2019 16:56:00 | BR28: 17.8 | BS28: 8/2/2019 16:56:00 | BT28: 12.79 | BU28: 8/2/2019 16:56:00 | BV28: 102673,68 | BW28: 8/2/2019 16:56:00 | BX28: 29,1
B29: 29 | C29: 8/5/2019 16:56:00 | D29: 18.25 | E29: 8/5/2019 16:56:00 | F29: 31.59 | G29: 8/5/2019 16:56:00 | H29: 47.4 | I29: 8/5/2019 16:56:00 | J29: 12.22 | K29: 8/5/2019 16:56:00 | L29: 19.76 | M29: 8/5/2019 16:56:00 | N29: 12.26 | O29: 8/5/2019 16:56:00 | P29: 29.67 | Q29: 8/5/2019 16:56:00 | R29: 24.51 | S29: 8/5/2019 16:56:00 | T29: 20.37 | U29: 8/5/2019 16:56:00 | V29: 5.27 | W29: 8/5/2019 16:56:00 | X29: 115.5 | Y29: 8/5/2019 16:56:00 | Z29: 28.01 | AA29: 8/5/2019 16:56:00 | AB29: 23.97 | AC29: 8/5/2019 16:56:00 | AD29: 18.63 | AE29: 8/5/2019 16:56:00 | AF29: 31.5 | AG29: 8/5/2019 16:56:00 | AH29: 46 | AI29: 8/5/2019 16:56:00 | AJ29: 44.01 | AK29: 8/5/2019 16:56:00 | AL29: 6.91 | AM29: 8/5/2019 16:56:00 | AN29: 98.51 | AO29: 8/5/2019 16:56:00 | AP29: 116.16 | AQ29: 8/5/2019 16:56:00 | AR29: 11.6 | AS29: 8/5/2019 16:56:00 | AT29: 1235.98 | AU29: 8/5/2019 16:56:00 | AV29: 141.5 | AW29: 8/5/2019 16:56:00 | AX29: 119.93 | AY29: 8/5/2019 16:56:00 | AZ29: 4.23 | BA29: 8/5/2019 16:56:00 | BB29: 153.8 | BC29: 8/5/2019 16:56:00 | BD29: 17 | BE29: 8/5/2019 16:56:00 | BF29: 12.75 | BG29: 8/5/2019 16:56:00 | BH29: 38.8 | BI29: 8/5/2019 16:56:00 | BJ29: 153.8 | BK29: 8/5/2019 16:56:00 | BL29: 23.3 | BM29: 8/5/2019 16:56:00 | BN29: 41.47 | BO29: 8/5/2019 16:56:00 | BP29: 25.55 | BQ29: 8/5/2019 16:56:00 | BR29: 17.62 | BS29: 8/5/2019 16:56:00 | BT29: 12.53 | BU29: 8/5/2019 16:56:00 | BV29: 100097,75 | BW29: 8/5/2019 16:56:00 | BX29: 28,85
B30: 30 | C30: 8/6/2019 16:56:00 | D30: 19.12 | E30: 8/6/2019 16:56:00 | F30: 32.36 | G30: 8/6/2019 16:56:00 | H30: 48.5 | I30: 8/6/2019 16:56:00 | J30: 12.15 | K30: 8/6/2019 16:56:00 | L30: 20.3 | M30: 8/6/2019 16:56:00 | N30: 12.66 | O30: 8/6/2019 16:56:00 | P30: 30.6 | Q30: 8/6/2019 16:56:00 | R30: 24.75 | S30: 8/6/2019 16:56:00 | T30: 21.35 | U30: 8/6/2019 16:56:00 | V30: 5.33 | W30: 8/6/2019 16:56:00 | X30: 113 | Y30: 8/6/2019 16:56:00 | Z30: 28.79 | AA30: 8/6/2019 16:56:00 | AB30: 24.32 | AC30: 8/6/2019 16:56:00 | AD30: 18.58 | AE30: 8/6/2019 16:56:00 | AF30: 31.61 | AG30: 8/6/2019 16:56:00 | AH30: 46.62 | AI30: 8/6/2019 16:56:00 | AJ30: 44.59 | AK30: 8/6/2019 16:56:00 | AL30: 7.25 | AM30: 8/6/2019 16:56:00 | AN30: 98.85 | AO30: 8/6/2019 16:56:00 | AP30: 116.25 | AQ30: 8/6/2019 16:56:00 | AR30: 11.31 | AS30: 8/6/2019 16:56:00 | AT30: 1230.15 | AU30: 8/6/2019 16:56:00 | AV30: 141.05 | AW30: 8/6/2019 16:56:00 | AX30: 120 | AY30: 8/6/2019 16:56:00 | AZ30: 4.22 | BA30: 8/6/2019 16:56:00 | BB30: 152.82 | BC30: 8/6/2019 16:56:00 | BD30: 17.9 | BE30: 8/6/2019 16:56:00 | BF30: 12.68 | BG30: 8/6/2019 16:56:00 | BH30: 39.72 | BI30: 8/6/2019 16:56:00 | BJ30: 154.6 | BK30: 8/6/2019 16:56:00 | BL30: 23.9 | BM30: 8/6/2019 16:56:00 | BN30: 42.8 | BO30: 8/6/2019 16:56:00 | BP30: 25.88 | BQ30: 8/6/2019 16:56:00 | BR30: 17.6 | BS30: 8/6/2019 16:56:00 | BT30: 12.6 | BU30: 8/6/2019 16:56:00 | BV30: 102163,69 | BW30: 8/6/2019 16:56:00 | BX30: 29,08
B31: 31 | C31: 8/7/2019 16:56:00 | D31: 19.05 | E31: 8/7/2019 16:56:00 | F31: 33.02 | G31: 8/7/2019 16:56:00 | H31: 47.4 | I31: 8/7/2019 16:56:00 | J31: 12.45 | K31: 8/7/2019 16:56:00 | L31: 20.25 | M31: 8/7/2019 16:56:00 | N31: 12.99 | O31: 8/7/2019 16:56:00 | P31: 31.8 | Q31: 8/7/2019 16:56:00 | R31: 24.8 | S31: 8/7/2019 16:56:00 | T31: 21.65 | U31: 8/7/2019 16:56:00 | V31: 5.25 | W31: 8/7/2019 16:56:00 | X31: 115.5 | Y31: 8/7/2019 16:56:00 | Z31: 28.69 | AA31: 8/7/2019 16:56:00 | AB31: 24.53 | AC31: 8/7/2019 16:56:00 | AD31: 18.56 | AE31: 8/7/2019 16:56:00 | AF31: 31 | AG31: 8/7/2019 16:56:00 | AH31: 46.48 | AI31: 8/7/2019 16:56:00 | AJ31: 45.24 | AK31: 8/7/2019 16:56:00 | AL31: 7.29 | AM31: 8/7/2019 16:56:00 | AN31: 98.3 | AO31: 8/7/2019 16:56:00 | AP31: 116.75 | AQ31: 8/7/2019 16:56:00 | AR31: 11.32 | AS31: 8/7/2019 16:56:00 | AT31: 1234 | AU31: 8/7/2019 16:56:00 | AV31: 142.4 | AW31: 8/7/2019 16:56:00 | AX31: 120 | AY31: 8/7/2019 16:56:00 | AZ31: 4.23 | BA31: 8/7/2019 16:56:00 | BB31: 150.89 | BC31: 8/7/2019 16:56:00 | BD31: 18.23 | BE31: 8/7/2019 16:56:00 | BF31: 13.13 | BG31: 8/7/2019 16:56:00 | BH31: 39.65 | BI31: 8/7/2019 16:56:00 | BJ31: 154.49 | BK31: 8/7/2019 16:56:00 | BL31: 24.31 | BM31: 8/7/2019 16:56:00 | BN31: 43.44 | BO31: 8/7/2019 16:56:00 | BP31: 25.6 | BQ31: 8/7/2019 16:56:00 | BR31: 17.43 | BS31: 8/7/2019 16:56:00 | BT31: 12.55 | BU31: 8/7/2019 16:56:00 | BV31: 102782,37 | BW31: 8/7/2019 16:56:00 | BX31: 28,83
B32: 32 | C32: 8/8/2019 16:56:00 | D32: 18.97 | E32: 8/8/2019 16:56:00 | F32: 34.44 | G32: 8/8/2019 16:56:00 | H32: 47.5 | I32: 8/8/2019 16:56:00 | J32: 12.01 | K32: 8/8/2019 16:56:00 | L32: 20.56 | M32: 8/8/2019 16:56:00 | N32: 13.12 | O32: 8/8/2019 16:56:00 | P32: 31.81 | Q32: 8/8/2019 16:56:00 | R32: 25.52 | S32: 8/8/2019 16:56:00 | T32: 22.64 | U32: 8/8/2019 16:56:00 | V32: 5.24 | W32: 8/8/2019 16:56:00 | X32: 115.75 | Y32: 8/8/2019 16:56:00 | Z32: 28.83 | AA32: 8/8/2019 16:56:00 | AB32: 24.55 | AC32: 8/8/2019 16:56:00 | AD32: 18.47 | AE32: 8/8/2019 16:56:00 | AF32: 31.5 | AG32: 8/8/2019 16:56:00 | AH32: 47.18 | AI32: 8/8/2019 16:56:00 | AJ32: 45.6 | AK32: 8/8/2019 16:56:00 | AL32: 7.71 | AM32: 8/8/2019 16:56:00 | AN32: 95.3 | AO32: 8/8/2019 16:56:00 | AP32: 117.09 | AQ32: 8/8/2019 16:56:00 | AR32: 11.11 | AS32: 8/8/2019 16:56:00 | AT32: 1224 | AU32: 8/8/2019 16:56:00 | AV32: 141.7 | AW32: 8/8/2019 16:56:00 | AX32: 120.02 | AY32: 8/8/2019 16:56:00 | AZ32: 4.22 | BA32: 8/8/2019 16:56:00 | BB32: 151.83 | BC32: 8/8/2019 16:56:00 | BD32: 19.1 | BE32: 8/8/2019 16:56:00 | BF32: 13.43 | BG32: 8/8/2019 16:56:00 | BH32: 40.2 | BI32: 8/8/2019 16:56:00 | BJ32: 154.12 | BK32: 8/8/2019 16:56:00 | BL32: 24.44 | BM32: 8/8/2019 16:56:00 | BN32: 45.33 | BO32: 8/8/2019 16:56:00 | BP32: 26.35 | BQ32: 8/8/2019 16:56:00 | BR32: 17.48 | BS32: 8/8/2019 16:56:00 | BT32: 12.51 | BU32: 8/8/2019 16:56:00 | BV32: 104115,23 | BW32: 8/8/2019 16:56:00 | BX32: 28,97
B33: 33 | C33: 8/9/2019 16:56:00 | D33: 19.31 | E33: 8/9/2019 16:56:00 | F33: 35.45 | G33: 8/9/2019 16:56:00 | H33: 47.86 | I33: 8/9/2019 16:56:00 | J33: 11.85 | K33: 8/9/2019 16:56:00 | L33: 20.61 | M33: 8/9/2019 16:56:00 | N33: 13.06 | O33: 8/9/2019 16:56:00 | P33: 31.81 | Q33: 8/9/2019 16:56:00 | R33: 25.65 | S33: 8/9/2019 16:56:00 | T33: 21.25 | U33: 8/9/2019 16:56:00 | V33: 5.31 | W33: 8/9/2019 16:56:00 | X33: 115.7 | Y33: 8/9/2019 16:56:00 | Z33: 28.25 | AA33: 8/9/2019 16:56:00 | AB33: 24.83 | AC33: 8/9/2019 16:56:00 | AD33: 18.75 | AE33: 8/9/2019 16:56:00 | AF33: 31.75 | AG33: 8/9/2019 16:56:00 | AH33: 45.49 | AI33: 8/9/2019 16:56:00 | AJ33: 44.83 | AK33: 8/9/2019 16:56:00 | AL33: 7.72 | AM33: 8/9/2019 16:56:00 | AN33: 92 | AO33: 8/9/2019 16:56:00 | AP33: 116.95 | AQ33: 8/9/2019 16:56:00 | AR33: 11.09 | AS33: 8/9/2019 16:56:00 | AT33: 1200 | AU33: 8/9/2019 16:56:00 | AV33: 141.9 | AW33: 8/9/2019 16:56:00 | AX33: 120.12 | AY33: 8/9/2019 16:56:00 | AZ33: 4.21 | BA33: 8/9/2019 16:56:00 | BB33: 150.5 | BC33: 8/9/2019 16:56:00 | BD33: 18.7 | BE33: 8/9/2019 16:56:00 | BF33: 13.49 | BG33: 8/9/2019 16:56:00 | BH33: 42.25 | BI33: 8/9/2019 16:56:00 | BJ33: 154.4 | BK33: 8/9/2019 16:56:00 | BL33: 24.18 | BM33: 8/9/2019 16:56:00 | BN33: 45.5 | BO33: 8/9/2019 16:56:00 | BP33: 26.28 | BQ33: 8/9/2019 16:56:00 | BR33: 17.61 | BS33: 8/9/2019 16:56:00 | BT33: 12.63 | BU33: 8/9/2019 16:56:00 | BV33: 103996,16 | BW33: 8/9/2019 16:56:00 | BX33: 28,7
B34: 34 | C34: 8/12/2019 16:56:00 | D34: 19.65 | E34: 8/12/2019 16:56:00 | F34: 33.7 | G34: 8/12/2019 16:56:00 | H34: 47.2 | I34: 8/12/2019 16:56:00 | J34: 11.84 | K34: 8/12/2019 16:56:00 | L34: 20.42 | M34: 8/12/2019 16:56:00 | N34: 12.6 | O34: 8/12/2019 16:56:00 | P34: 30.66 | Q34: 8/12/2019 16:56:00 | R34: 25.86 | S34: 8/12/2019 16:56:00 | T34: 21.08 | U34: 8/12/2019 16:56:00 | V34: 5.25 | W34: 8/12/2019 16:56:00 | X34: 115 | Y34: 8/12/2019 16:56:00 | Z34: 28.29 | AA34: 8/12/2019 16:56:00 | AB34: 24.85 | AC34: 8/12/2019 16:56:00 | AD34: 18.36 | AE34: 8/12/2019 16:56:00 | AF34: 31.5 | AG34: 8/12/2019 16:56:00 | AH34: 45.16 | AI34: 8/12/2019 16:56:00 | AJ34: 44.99 | AK34: 8/12/2019 16:56:00 | AL34: 7.47 | AM34: 8/12/2019 16:56:00 | AN34: 93.37 | AO34: 8/12/2019 16:56:00 | AP34: 116 | AQ34: 8/12/2019 16:56:00 | AR34: 11.01 | AS34: 8/12/2019 16:56:00 | AT34: 1190.1 | AU34: 8/12/2019 16:56:00 | AV34: 140.94 | AW34: 8/12/2019 16:56:00 | AX34: 120.05 | AY34: 8/12/2019 16:56:00 | AZ34: 4.21 | BA34: 8/12/2019 16:56:00 | BB34: 149.99 | BC34: 8/12/2019 16:56:00 | BD34: 18.33 | BE34: 8/12/2019 16:56:00 | BF34: 13.35 | BG34: 8/12/2019 16:56:00 | BH34: 38.9 | BI34: 8/12/2019 16:56:00 | BJ34: 155.4 | BK34: 8/12/2019 16:56:00 | BL34: 23.75 | BM34: 8/12/2019 16:56:00 | BN34: 44.24 | BO34: 8/12/2019 16:56:00 | BP34: 25.65 | BQ34: 8/12/2019 16:56:00 | BR34: 17.39 | BS34: 8/12/2019 16:56:00 | BT34: 12.39 | BU34: 8/12/2019 16:56:00 | BV34: 101915,22 | BW34: 8/12/2019 16:56:00 | BX34: 27,9
B35: 35 | C35: 8/13/2019 16:56:00 | D35: 19.81 | E35: 8/13/2019 16:56:00 | F35: 34.07 | G35: 8/13/2019 16:56:00 | H35: 47.9 | I35: 8/13/2019 16:56:00 | J35: 12.1 | K35: 8/13/2019 16:56:00 | L35: 20.42 | M35: 8/13/2019 16:56:00 | N35: 12.92 | O35: 8/13/2019 16:56:00 | P35: 30.95 | Q35: 8/13/2019 16:56:00 | R35: 25.2 | S35: 8/13/2019 16:56:00 | T35: 20.27 | U35: 8/13/2019 16:56:00 | V35: 5.22 | W35: 8/13/2019 16:56:00 | X35: 115 | Y35: 8/13/2019 16:56:00 | Z35: 28.78 | AA35: 8/13/2019 16:56:00 | AB35: 24.99 | AC35: 8/13/2019 16:56:00 | AD35: 18.65 | AE35: 8/13/2019 16:56:00 | AF35: 31.91 | AG35: 8/13/2019 16:56:00 | AH35: 46.5 | AI35: 8/13/2019 16:56:00 | AJ35: 44.18 | AK35: 8/13/2019 16:56:00 | AL35: 7.45 | AM35: 8/13/2019 16:56:00 | AN35: 94.45 | AO35: 8/13/2019 16:56:00 | AP35: 117 | AQ35: 8/13/2019 16:56:00 | AR35: 10.99 | AS35: 8/13/2019 16:56:00 | AT35: 1181.02 | AU35: 8/13/2019 16:56:00 | AV35: 140.15 | AW35: 8/13/2019 16:56:00 | AX35: 120.09 | AY35: 8/13/2019 16:56:00 | AZ35: 4.19 | BA35: 8/13/2019 16:56:00 | BB35: 149.72 | BC35: 8/13/2019 16:56:00 | BD35: 18.4 | BE35: 8/13/2019 16:56:00 | BF35: 13.63 | BG35: 8/13/2019 16:56:00 | BH35: 38.3 | BI35: 8/13/2019 16:56:00 | BJ35: 154.01 | BK35: 8/13/2019 16:56:00 | BL35: 24.28 | BM35: 8/13/2019 16:56:00 | BN35: 45.86 | BO35: 8/13/2019 16:56:00 | BP35: 25.79 | BQ35: 8/13/2019 16:56:00 | BR35: 17.55 | BS35: 8/13/2019 16:56:00 | BT35: 12.29 | BU35: 8/13/2019 16:56:00 | BV35: 103299,47 | BW35: 8/13/2019 16:56:00 | BX35: 28,24
B36: 36 | C36: 8/14/2019 16:56:00 | D36: 19.91 | E36: 8/14/2019 16:56:00 | F36: 33.34 | G36: 8/14/2019 16:56:00 | H36: 46.17 | I36: 8/14/2019 16:56:00 | J36: 11.96 | K36: 8/14/2019 16:56:00 | L36: 19.9 | M36: 8/14/2019 16:56:00 | N36: 12.75 | O36: 8/14/2019 16:56:00 | P36: 30.4 | Q36: 8/14/2019 16:56:00 | R36: 24.56 | S36: 8/14/2019 16:56:00 | T36: 19.36 | U36: 8/14/2019 16:56:00 | V36: 5.13 | W36: 8/14/2019 16:56:00 | X36: 115 | Y36: 8/14/2019 16:56:00 | Z36: 28.07 | AA36: 8/14/2019 16:56:00 | AB36: 24.78 | AC36: 8/14/2019 16:56:00 | AD36: 18.19 | AE36: 8/14/2019 16:56:00 | AF36: 29.95 | AG36: 8/14/2019 16:56:00 | AH36: 44.88 | AI36: 8/14/2019 16:56:00 | AJ36: 43.2 | AK36: 8/14/2019 16:56:00 | AL36: 7.12 | AM36: 8/14/2019 16:56:00 | AN36: 93.3 | AO36: 8/14/2019 16:56:00 | AP36: 117.25 | AQ36: 8/14/2019 16:56:00 | AR36: 10.99 | AS36: 8/14/2019 16:56:00 | AT36: 1200 | AU36: 8/14/2019 16:56:00 | AV36: 140.17 | AW36: 8/14/2019 16:56:00 | AX36: 120 | AY36: 8/14/2019 16:56:00 | AZ36: 4.19 | BA36: 8/14/2019 16:56:00 | BB36: 150.84 | BC36: 8/14/2019 16:56:00 | BD36: 17.94 | BE36: 8/14/2019 16:56:00 | BF36: 13.38 | BG36: 8/14/2019 16:56:00 | BH36: 37.45 | BI36: 8/14/2019 16:56:00 | BJ36: 155 | BK36: 8/14/2019 16:56:00 | BL36: 23.09 | BM36: 8/14/2019 16:56:00 | BN36: 43.7 | BO36: 8/14/2019 16:56:00 | BP36: 24.92 | BQ36: 8/14/2019 16:56:00 | BR36: 17.13 | BS36: 8/14/2019 16:56:00 | BT36: 11.98 | BU36: 8/14/2019 16:56:00 | BV36: 100258,01 | BW36: 8/14/2019 16:56:00 | BX36: 27,35
B37: 37 | C37: 8/15/2019 16:56:00 | D37: 19.08 | E37: 8/15/2019 16:56:00 | F37: 33.1 | G37: 8/15/2019 16:56:00 | H37: 45.35 | I37: 8/15/2019 16:56:00 | J37: 11.53 | K37: 8/15/2019 16:56:00 | L37: 19.48 | M37: 8/15/2019 16:56:00 | N37: 12.8 | O37: 8/15/2019 16:56:00 | P37: 30.19 | Q37: 8/15/2019 16:56:00 | R37: 23.87 | S37: 8/15/2019 16:56:00 | T37: 18.72 | U37: 8/15/2019 16:56:00 | V37: 4.89 | W37: 8/15/2019 16:56:00 | X37: 115 | Y37: 8/15/2019 16:56:00 | Z37: 27.6 | AA37: 8/15/2019 16:56:00 | AB37: 23.93 | AC37: 8/15/2019 16:56:00 | AD37: 17.77 | AE37: 8/15/2019 16:56:00 | AF37: 27.3 | AG37: 8/15/2019 16:56:00 | AH37: 43.89 | AI37: 8/15/2019 16:56:00 | AJ37: 43.3 | AK37: 8/15/2019 16:56:00 | AL37: 6.71 | AM37: 8/15/2019 16:56:00 | AN37: 93.6 | AO37: 8/15/2019 16:56:00 | AP37: 117.18 | AQ37: 8/15/2019 16:56:00 | AR37: 10.9 | AS37: 8/15/2019 16:56:00 | AT37: 1188.01 | AU37: 8/15/2019 16:56:00 | AV37: 139.82 | AW37: 8/15/2019 16:56:00 | AX37: 119.19 | AY37: 8/15/2019 16:56:00 | AZ37: 4.25 | BA37: 8/15/2019 16:56:00 | BB37: 150.25 | BC37: 8/15/2019 16:56:00 | BD37: 17.59 | BE37: 8/15/2019 16:56:00 | BF37: 12.78 | BG37: 8/15/2019 16:56:00 | BH37: 36.4 | BI37: 8/15/2019 16:56:00 | BJ37: 155.95 | BK37: 8/15/2019 16:56:00 | BL37: 22.35 | BM37: 8/15/2019 16:56:00 | BN37: 43.35 | BO37: 8/15/2019 16:56:00 | BP37: 24.23 | BQ37: 8/15/2019 16:56:00 | BR37: 16.7 | BS37: 8/15/2019 16:56:00 | BT37: 11.68 | BU37: 8/15/2019 16:56:00 | BV37: 99056,91 | BW37: 8/15/2019 16:56:00 | BX37: 27,15
B38: 38 | C38: 8/16/2019 16:56:00 | D38: 18.97 | E38: 8/16/2019 16:56:00 | F38: 33.24 | G38: 8/16/2019 16:56:00 | H38: 45.15 | I38: 8/16/2019 16:56:00 | J38: 11.25 | K38: 8/16/2019 16:56:00 | L38: 19.85 | M38: 8/16/2019 16:56:00 | N38: 12.51 | O38: 8/16/2019 16:56:00 | P38: 29.52 | Q38: 8/16/2019 16:56:00 | R38: 23.7 | S38: 8/16/2019 16:56:00 | T38: 18.4 | U38: 8/16/2019 16:56:00 | V38: 4.86 | W38: 8/16/2019 16:56:00 | X38: 114.86 | Y38: 8/16/2019 16:56:00 | Z38: 27.6 | AA38: 8/16/2019 16:56:00 | AB38: 24.05 | AC38: 8/16/2019 16:56:00 | AD38: 17.72 | AE38: 8/16/2019 16:56:00 | AF38: 27.47 | AG38: 8/16/2019 16:56:00 | AH38: 43.69 | AI38: 8/16/2019 16:56:00 | AJ38: 43.5 | AK38: 8/16/2019 16:56:00 | AL38: 6.78 | AM38: 8/16/2019 16:56:00 | AN38: 95 | AO38: 8/16/2019 16:56:00 | AP38: 117 | AQ38: 8/16/2019 16:56:00 | AR38: 10.87 | AS38: 8/16/2019 16:56:00 | AT38: 1198.99 | AU38: 8/16/2019 16:56:00 | AV38: 142 | AW38: 8/16/2019 16:56:00 | AX38: 119.5 | AY38: 8/16/2019 16:56:00 | AZ38: 4.3 | BA38: 8/16/2019 16:56:00 | BB38: 151.39 | BC38: 8/16/2019 16:56:00 | BD38: 17.77 | BE38: 8/16/2019 16:56:00 | BF38: 12.62 | BG38: 8/16/2019 16:56:00 | BH38: 37.25 | BI38: 8/16/2019 16:56:00 | BJ38: 156 | BK38: 8/16/2019 16:56:00 | BL38: 22.8 | BM38: 8/16/2019 16:56:00 | BN38: 44.5 | BO38: 8/16/2019 16:56:00 | BP38: 23.91 | BQ38: 8/16/2019 16:56:00 | BR38: 16.08 | BS38: 8/16/2019 16:56:00 | BT38: 11.75 | BU38: 8/16/2019 16:56:00 | BV38: 99805,78 | BW38: 8/16/2019 16:56:00 | BX38: 27,5
B39: 39 | C39: 8/19/2019 16:56:00 | D39: 18.77 | E39: 8/19/2019 16:56:00 | F39: 33.15 | G39: 8/19/2019 16:56:00 | H39: 45.15 | I39: 8/19/2019 16:56:00 | J39: 11.03 | K39: 8/19/2019 16:56:00 | L39: 19.75 | M39: 8/19/2019 16:56:00 | N39: 12.29 | O39: 8/19/2019 16:56:00 | P39: 29.4 | Q39: 8/19/2019 16:56:00 | R39: 23.75 | S39: 8/19/2019 16:56:00 | T39: 18.1 | U39: 8/19/2019 16:56:00 | V39: 4.91 | W39: 8/19/2019 16:56:00 | X39: 115 | Y39: 8/19/2019 16:56:00 | Z39: 27.38 | AA39: 8/19/2019 16:56:00 | AB39: 24.15 | AC39: 8/19/2019 16:56:00 | AD39: 17.32 | AE39: 8/19/2019 16:56:00 | AF39: 27.93 | AG39: 8/19/2019 16:56:00 | AH39: 43.65 | AI39: 8/19/2019 16:56:00 | AJ39: 43.1 | AK39: 8/19/2019 16:56:00 | AL39: 6.74 | AM39: 8/19/2019 16:56:00 | AN39: 94.13 | AO39: 8/19/2019 16:56:00 | AP39: 117.08 | AQ39: 8/19/2019 16:56:00 | AR39: 10.82 | AS39: 8/19/2019 16:56:00 | AT39: 1178 | AU39: 8/19/2019 16:56:00 | AV39: 141.63 | AW39: 8/19/2019 16:56:00 | AX39: 119.3 | AY39: 8/19/2019 16:56:00 | AZ39: 4.3 | BA39: 8/19/2019 16:56:00 | BB39: 151 | BC39: 8/19/2019 16:56:00 | BD39: 17.34 | BE39: 8/19/2019 16:56:00 | BF39: 14.03 | BG39: 8/19/2019 16:56:00 | BH39: 36.95 | BI39: 8/19/2019 16:56:00 | BJ39: 156.9 | BK39: 8/19/2019 16:56:00 | BL39: 22.54 | BM39: 8/19/2019 16:56:00 | BN39: 45.5 | BO39: 8/19/2019 16:56:00 | BP39: 24.03 | BQ39: 8/19/2019 16:56:00 | BR39: 16.2 | BS39: 8/19/2019 16:56:00 | BT39: 11.74 | BU39: 8/19/2019 16:56:00 | BV39: 99468,67 | BW39: 8/19/2019 16:56:00 | BX39: 27,61
B40: 40 | C40: 8/20/2019 16:56:00 | D40: 18.75 | E40: 8/20/2019 16:56:00 | F40: 33.08 | G40: 8/20/2019 16:56:00 | H40: 44.31 | I40: 8/20/2019 16:56:00 | J40: 11.13 | K40: 8/20/2019 16:56:00 | L40: 19.35 | M40: 8/20/2019 16:56:00 | N40: 12.1 | O40: 8/20/2019 16:56:00 | P40: 29.16 | Q40: 8/20/2019 16:56:00 | R40: 23.49 | S40: 8/20/2019 16:56:00 | T40: 17.81 | U40: 8/20/2019 16:56:00 | V40: 4.95 | W40: 8/20/2019 16:56:00 | X40: 115 | Y40: 8/20/2019 16:56:00 | Z40: 27 | AA40: 8/20/2019 16:56:00 | AB40: 23.69 | AC40: 8/20/2019 16:56:00 | AD40: 17.23 | AE40: 8/20/2019 16:56:00 | AF40: 28.09 | AG40: 8/20/2019 16:56:00 | AH40: 43.84 | AI40: 8/20/2019 16:56:00 | AJ40: 44.73 | AK40: 8/20/2019 16:56:00 | AL40: 6.8 | AM40: 8/20/2019 16:56:00 | AN40: 93.2 | AO40: 8/20/2019 16:56:00 | AP40: 117.07 | AQ40: 8/20/2019 16:56:00 | AR40: 10.79 | AS40: 8/20/2019 16:56:00 | AT40: 1149.25 | AU40: 8/20/2019 16:56:00 | AV40: 139.8 | AW40: 8/20/2019 16:56:00 | AX40: 117.75 | AY40: 8/20/2019 16:56:00 | AZ40: 4.25 | BA40: 8/20/2019 16:56:00 | BB40: 150.99 | BC40: 8/20/2019 16:56:00 | BD40: 17.5 | BE40: 8/20/2019 16:56:00 | BF40: 13.75 | BG40: 8/20/2019 16:56:00 | BH40: 36.71 | BI40: 8/20/2019 16:56:00 | BJ40: 157.1 | BK40: 8/20/2019 16:56:00 | BL40: 22.6 | BM40: 8/20/2019 16:56:00 | BN40: 45.76 | BO40: 8/20/2019 16:56:00 | BP40: 24.02 | BQ40: 8/20/2019 16:56:00 | BR40: 15.68 | BS40: 8/20/2019 16:56:00 | BT40: 11.73 | BU40: 8/20/2019 16:56:00 | BV40: 99222,25 | BW40: 8/20/2019 16:56:00 | BX40: 26,82
...

Sheet Profit
A1: Data | B1: TAEE11 | C1: TIET11
A2: 43608 | B2: 23.33 | C2: 10.32
A3: 43609 | B3: 23.2 | C3: 10.31
A4: 43612 | B4: 23.28 | C4: 10.32
A5: 43613 | B5: 23.79 | C5: 10.51
A6: 43614 | B6: 23.66 | C6: 10.56
A7: 43615 | B7: 23.72 | C7: 10.62
A8: 43616 | B8: 24.52 | C8: 10.87
A9: 43619 | B9: 24.44 | C9: 10.74
A10: 43620 | B10: 24.54 | C10: 10.85
A11: 43621 | B11: 24.64 | C11: 10.83
A12: 43622 | B12: 25.15 | C12: 10.97
A13: 43623 | B13: 25.37 | C13: 11.02
... A249: 43972 | B249: 27.92 | C249: 13.6

Sheet Valorização
A1: DATA | B1: ABCB4 | C1: BBSE3 | D1: EGIE3 | E1: ENAT3 | F1: ENBR3 | G1: ITSA4 | H1: ITUB3 | I1: LEVE3 | J1: MRVE3 | K1: SAPR4 | L1: SDIL11 | M1: TAEE11 | N1: TRPL4 | O1: TUPY3 | P1: UNIP6 | Q1: VALE3 | R1: VIVT3 | S1: VULC3 | T1: BCFF11 | U1: HGCR11 | V1: MXRF11 | W1: MBRF11 | X1: GGRC11 | Y1: MFII11 | Z1: FLMA11 | AA1: HGLG11 | AB1: LCAM3 | AC1: SQIA3 | AD1: MDIA3 | AE1: KNRI11 | AF1: WEGE3 | AG1: B3SA3 | AH1: PETR4 | AI1: PRIO3 | AJ1: TIET11 | AK1: IBOV | AL1: CESP6 | AN1: Resumo ativos | AO1: ABCB4 | AP1: BBSE3 | AQ1: EGIE3 | AR1: ENAT3 | AS1: ENBR3 | AT1: ITSA4 | AU1: ITUB3 | AV1: LEVE3 | AW1: MRVE3 | AX1: SAPR4 | AY1: SDIL11 | AZ1: TAEE11 | BA1: TRPL4 | BB1: TUPY3 | BC1: UNIP6 | BD1: VALE3 | BE1: VIVT3 | BF1: VULC3 | BG1: BCFF11 | BH1: HGCR11 | BI1: MXRF11 | BJ1: MBRF11 | BK1: GGRC11 | BL1: MFII11 | BM1: FLMA11 | BN1: HGLG11 | BO1: LCAM3 | BP1: SQIA3 | BQ1: MDIA3 | BR1: KNRI11 | BS1: WEGE3 | BT1: B3SA3 | BU1: PETR4 | BV1: PRIO3 | BW1: TIET11 | BX1: IBOV | BY1: CESP6
A2: 1/2/2018 16:56:00 | AN2: Máximo
